Workbook
Name QCATP_P: [1]QCACTUAL!$C$2:$D$4
Name QCATP_P: [1]QCACTUAL!$C$2:$D$4
Name QCATP_P: QCACTUAL!$C$2:$D$4
Name QCATP_P: [1]QCACTUAL!$C$2:$D$4
Name QCATP_P: QCACTUAL!$C$2:$D$4
Name QCCHK: [1]QCACTUAL!$B$8:$D$22
Name QCCHK: [1]QCACTUAL!$B$8:$D$22
Name QCCHK: QCACTUAL!$B$8:$D$22
Name QCCHK: [1]QCACTUAL!$B$8:$D$22
Name QCCHK: QCACTUAL!$B$8:$D$22
Name QCEQUATIONS: [1]QCEQUATIONS!$A$2:$B$11
Name QCEQUATIONS: [1]QCEQUATIONS!$A$2:$B$11
Name QCEQUATIONS: [1]QCEQUATIONS!$A$2:$B$11
Name QCEQUATIONS: QCEQUATIONS!$A$2:$B$11
Name QCEQUATIONS: QCEQUATIONS!$A$2:$B$11
Name QCGUP: [1]QCACTUAL!$C$23:$D$25
Name QCGUP: [1]QCACTUAL!$C$23:$D$25
Name QCGUP: QCACTUAL!$C$23:$D$25
Name QCGUP: [1]QCACTUAL!$C$23:$D$25
Name QCGUP: QCACTUAL!$C$23:$D$25
Name QCNIC_N: [1]QCACTUAL!$C$44:$D$47
Name QCNIC_N: [1]QCACTUAL!$C$44:$D$47
Name QCNIC_N: QCACTUAL!$C$44:$D$47
Name QCNIC_N: [1]QCACTUAL!$C$44:$D$47
Name QCNIC_N: QCACTUAL!$C$44:$D$47
Name QCPER: [1]QCACTUAL!$J$25:$X$37
Name QCPER: [1]QCACTUAL!$J$25:$X$37
Name QCPER: QCACTUAL!$J$25:$AA$37
Name QCPER: [1]QCACTUAL!$J$25:$X$37
Name QCPER: QCACTUAL!$J$25:$AA$37
Name QCREC_N: [1]QCACTUAL!$C$40:$D$43
Name QCREC_N: [1]QCACTUAL!$C$40:$D$43
Name QCREC_N: QCACTUAL!$C$40:$D$43
Name QCREC_N: [1]QCACTUAL!$C$40:$D$43
Name QCREC_N: QCACTUAL!$C$40:$D$43
Name QCSPK: [1]QCACTUAL!$B$26:$D$39
Name QCSPK: [1]QCACTUAL!$B$26:$D$39
Name QCSPK: QCACTUAL!$B$26:$D$39
Name QCSPK: [1]QCACTUAL!$B$26:$D$39
Name QCSPK: QCACTUAL!$B$26:$D$39
Name QCUREA_N: [1]QCACTUAL!$C$5:$D$7
Name QCUREA_N: [1]QCACTUAL!$C$5:$D$7
Name QCUREA_N: QCACTUAL!$C$5:$D$7
Name QCUREA_N: [1]QCACTUAL!$C$5:$D$7
Name QCUREA_N: QCACTUAL!$C$5:$D$7

Sheet 2025 Data
A1: cdate mmdd10. | B1: ctime time11. | C1: id $char12. | D1: subid $char9. | E1: pos $char4. | F1: rep 1. | G1: matrix $char2. | H1: tpe $char3. | I1: anal$char6. | J1: cup 3. | K1: ddate mmdd10. | L1: dtime time11. | M1: dilf 2. | N1: method $char5. | O1: parea 8. | P1: pht 8. | Q1: conc 10. | R1: unit $char6. | S1: cconc 10. | T1: caleq $char90. | U1: qcrec 8. | V1: qcact 8. | W1: qcflag $char5.
A2: Collection Date (CDATE) | B2: Collection Time (CTIME) | C2: site id (ID) | D2: long id (SUBID) | E2: CRoss id (POS) | F2: REP# | G2: MATRIX | H2: TYPE | I2: Analyte Name (ANALY) | J2: Autosampler-Cup Number (CUP) | K2: Analyte Detection Date (DDATE) | L2: Analyte Detection Time (DTIME) | M2: Dilution Factor | N2: METHOD | O2: Peak Area (PAREA) | P2: Peak Height (PHT) | Q2: Peak Concentration (CONC) | R2: UNIT | S2: Peak Concentration (corrected for dilution factor) | T2: Calibration Equation (CALEQ) | U2: QC-Recover (QCREC) | V2: QC-Actual (QCACT) | W2: QC-Flag (QCFLAG) | X2: QC-Equation (QCEQ) | Y2: Run file | Z2: NOTES | AA2: mm | AB2: dd | AD2: m/d/ | AE2: PasteAsValue | AF2: TP-TN Cal Curve ID | AG2: TP adjusted concentration <150 ppb (ug P/L) | AH2: TP adjusted concentration <300 ppb (ug P/L) | AI2: TP adjusted concentration <500 ppb (ug P/L) | AJ2: TN adjusted concentration <2800 ppb (ug P/L) | AK2: TP-TN adjusted concentration full series (ug P/L) | AL2: TP calculation <150 ppb (ug P/L) | AM2: TP calculation <300 ppb (ug P/L) | AN2: TP calculation <500 ppb (ug P/L) | AO2: TN calculation <2800 ppb (ug P/L) | AP2: TP-TN calculation full series (ug P/L) | AQ2: TP calibration eq < 150 ppb | AR2: TP calibration eq <300 ppb | AS2: TP calibration eq <500 ppb | AT2: TN calibration eq <2800 ppb | AU2: TP-TN calibration eq full series ppb | AV2: Combined ID
A3: 45500 | B3: 0 | C3: 1000 | D3: 1 | E3: Sh | F3: 1 | G3: DI | H3: BLK | I3: TNH4 | J3: 1 | K3: 45687 | L3: 0.46931713 | M3: 1 | N3: N-1.1 | O3: 0.048 | P3: 0.0306 | Q3: 2.92 | R3: ug-N/L | S3: =IF(OR(AND(I3<>"TP", I3<>"TDP",I3<>"TN", I3<>"TDN"),H3="CAL"), Q3*M3, IF(OR(AND(I3="TN", Q3>2500), AND(I3="TDN", Q3>2500)),MAX(Q3, AK3)*M3, IF(OR(AND(I3="TN", Q3<=2500), AND(I3="TDN", Q3<=2500)),MAX(Q3, AJ3,AK3)*M3, IF(OR(AND(I3="TP",Q3>500), AND(I3="TDP", Q3>500)),MAX(Q3,AK3)*M3,IF(OR(AND(I3="TP",Q3<=150), AND(I3="TDP", Q3<=150)),MAX(Q3,AG3:AI3,AK3)*M3,IF(OR(AND(I3="TP",Q3<=300), AND(I3="TDP", Q3<=300)),MAX(Q3,AH3,AI3,AK3)*M3,IF(OR(AND(I3="TP",Q3<=500), AND(I3="TDP", Q3<=500)),MAX(Q3,AI3,AK3)*M3,""))))))) -> 2.92 | T3: Conc = 0.169 * Area^2 + 60.8 * Area + 0.00 | U3: =IF(OR(H3="CHK",H3="ATP",H3="GUP",H3="PER", H3="NIC", H3="UREA"),(S3/V3*100),IF(H3="DUP",((ABS(S3-#REF!))/((#REF!+S3)/2))*100,IF(H3="SPK",((S3-#REF!)/V3*100),IF(OR(H3="LAB",H3="FLD",H3="ESF"),S3,"")))) | V3: =IF(H3="CHK",VLOOKUP(I3,QCCHK,3,),IF(H3="GUP",VLOOKUP(E3,QCGUP,2,),IF(AND(H3="ATP",OR(I3="TN",I3="TDN",I3="TNO2-3",I3="NO2-3")),VLOOKUP(E3,QCREC_N,2,),IF(AND(H3="NIC",OR(I3="TN",I3="TDN",I3="TNO2-3",I3="NO2-3")),VLOOKUP(E3,QCNIC_N,2,),IF(AND(H3="UREA",OR(I3="TN",I3="TDN",I3="TNO2-3",I3="NO2-3")),VLOOKUP(E3,QCUREA_N,2,),IF(H3="PER",VLOOKUP(I3,QCPER,MATCH(E3,QCACTUAL!$J$25:$AA$25,0),),IF(H3="SPK",VLOOKUP(I3,QCSPK,3,),IF(AND(H3="ATP",OR(I3="TP",I3="TDP")),VLOOKUP(E3,QCATP_P,2,),"")))))))) | W3: =IF(AND(OR(H3="PER",H3="ATP",H3="GUP",H3="CHK",H3="SPK", H3="NIC"),OR(U3>125,U3<75)),"FALSE",IF(AND(H3="DUP",OR(U3>25, U3<-25)),"FALSE",IF(AND(OR(H3="LAB",H3="FLD",H3="ESF"),U3>15),"FALSE","TRUE"))) -> TRUE | X3: =IF(ISNA(VLOOKUP(H3,QCEQUATIONS,2,)),"",(VLOOKUP(H3,QCEQUATIONS,2,))) | Y3: OM_1-30-2025_10-50-49AMadj-adj (8500).OMN | AL3: =IF($O3="", "", IF(AQ3<>"", SUBSTITUTE(SUBSTITUTE(AQ3, "x", "*"&$O3&"^", 1), "x", "*"&$O3, 1), "")) -> FALSE | AM3: =IF($O3="", "", IF(AR3<>"", SUBSTITUTE(SUBSTITUTE(AR3, "x", "*"&$O3&"^", 1), "x", "*"&$O3, 1), "")) -> FALSE | AN3: =IF($O3="", "", IF(AS3<>"", SUBSTITUTE(SUBSTITUTE(AS3, "x", "*"&$O3&"^", 1), "x", "*"&$O3, 1), "")) -> FALSE | AO3: =IF($O3="", "FALSE", IF(AT3<>"FALSE", SUBSTITUTE(SUBSTITUTE(AT3, "x", "*"&$O3&"^", 1), "x", "*"&$O3, 1), "")) -> FALSE | AP3: =IF($O3="", "FALSE", IF(AU3<>"FALSE", SUBSTITUTE(SUBSTITUTE(AU3, "x", "*"&$O3&"^", 1), "x", "*"&$O3, 1), "")) -> FALSE | AQ3: =IF(AND(I3="TP",S3<=150),VLOOKUP(AF3,TPCalibEq150!$AZ$2:$BB$166,3,),IF(AND(I3="TDP",S3<=150),VLOOKUP(AF3,TPCalibEq150!$AZ$2:$BB$166,3,))) -> FALSE | AR3: =IF(AND(I3="TP",S3<=300),VLOOKUP(AF3,TPCalibEq300!$AZ$2:$BB$166,3,),IF(AND(I3="TDP",S3<=300),VLOOKUP(AF3,TPCalibEq300!$AZ$2:$BB$166,3,))) -> FALSE | AS3: =IF(AND(I3="TP",S3<=500),VLOOKUP(AF3,TPCalibEq500!$AZ$2:$BB$165,3,),IF(AND(I3="TDP",S3<=500),VLOOKUP(AF3,TPCalibEq500!$AZ$2:$BB$165,3,))) -> FALSE | AT3: =IF(AND(I3="TN",S3<=2800),VLOOKUP(AF3,TNCalibEq2500!$AZ$2:$BB$165,3,),IF(AND(I3="TDN",S3<=2800),VLOOKUP(AF3,TNCalibEq2500!$AZ$2:$BB$165,3,))) -> FALSE | AU3: =IF(I3="TP",VLOOKUP(AF3,TPCalibEqFull!$AZ$2:$BB$165,3),IF(I3="TDP",VLOOKUP(AF3,TPCalibEqFull!$AZ$2:$BB$165,3),IF(I3="TDN",VLOOKUP(AF3,TNCalibEqFull!$AZ$2:$BB$164,3),IF(I3="TN",VLOOKUP(AF3,TNCalibEqFull!$AZ$2:$BB$164,3),FALSE)))) -> FALSE | AV3: =TEXT(A3, "YYYYMMDD")&" "&TEXT(B3, "HH:MM:SS")&"-"&C3&"-"&D3&"-"&E3&"-"&F3&"-"&G3&"-"&H3 -> 20240727 00:00:00-1000-1-Sh-1-DI-BLK
A4: 45500 | B4: 0 | C4: 1000 | D4: 1 | E4: Sh | F4: 1 | G4: SW | H4: UKN | I4: TNH4 | J4: 2 | K4: 45687 | L4: 0.47015046 | M4: 1 | N4: N-1.1 | O4: 0.218 | P4: 0.0313 | Q4: 13.3 | R4: ug-N/L | S4: =IF(OR(AND(I4<>"TP", I4<>"TDP",I4<>"TN", I4<>"TDN"),H4="CAL"), Q4*M4, IF(OR(AND(I4="TN", Q4>2500), AND(I4="TDN", Q4>2500)),MAX(Q4, AK4)*M4, IF(OR(AND(I4="TN", Q4<=2500), AND(I4="TDN", Q4<=2500)),MAX(Q4, AJ4,AK4)*M4, IF(OR(AND(I4="TP",Q4>500), AND(I4="TDP", Q4>500)),MAX(Q4,AK4)*M4,IF(OR(AND(I4="TP",Q4<=150), AND(I4="TDP", Q4<=150)),MAX(Q4,AG4:AI4,AK4)*M4,IF(OR(AND(I4="TP",Q4<=300), AND(I4="TDP", Q4<=300)),MAX(Q4,AH4,AI4,AK4)*M4,IF(OR(AND(I4="TP",Q4<=500), AND(I4="TDP", Q4<=500)),MAX(Q4,AI4,AK4)*M4,""))))))) -> 13.3 | T4: Conc = 0.169 * Area^2 + 60.8 * Area + 0.00 | U4: =IF(OR(H4="CHK",H4="ATP",H4="GUP",H4="PER", H4="NIC", H4="UREA"),(S4/V4*100),IF(H4="DUP",((ABS(S4-S3))/((S3+S4)/2))*100,IF(H4="SPK",((S4-S3)/V4*100),IF(OR(H4="LAB",H4="FLD",H4="ESF"),S4,"")))) | V4: =IF(H4="CHK",VLOOKUP(I4,QCCHK,3,),IF(H4="GUP",VLOOKUP(E4,QCGUP,2,),IF(AND(H4="ATP",OR(I4="TN",I4="TDN",I4="TNO2-3",I4="NO2-3")),VLOOKUP(E4,QCREC_N,2,),IF(AND(H4="NIC",OR(I4="TN",I4="TDN",I4="TNO2-3",I4="NO2-3")),VLOOKUP(E4,QCNIC_N,2,),IF(AND(H4="UREA",OR(I4="TN",I4="TDN",I4="TNO2-3",I4="NO2-3")),VLOOKUP(E4,QCUREA_N,2,),IF(H4="PER",VLOOKUP(I4,QCPER,MATCH(E4,QCACTUAL!$J$25:$AA$25,0),),IF(H4="SPK",VLOOKUP(I4,QCSPK,3,),IF(AND(H4="ATP",OR(I4="TP",I4="TDP")),VLOOKUP(E4,QCATP_P,2,),"")))))))) | W4: =IF(AND(OR(H4="PER",H4="ATP",H4="GUP",H4="CHK",H4="SPK", H4="NIC"),OR(U4>125,U4<75)),"FALSE",IF(AND(H4="DUP",OR(U4>25, U4<-25)),"FALSE",IF(AND(OR(H4="LAB",H4="FLD",H4="ESF"),U4>15),"FALSE","TRUE"))) -> TRUE | X4: =IF(ISNA(VLOOKUP(H4,QCEQUATIONS,2,)),"",(VLOOKUP(H4,QCEQUATIONS,2,))) | Y4: OM_1-30-2025_10-50-49AMadj-adj (8500).OMN | AL4: =IF($O4="", "", IF(AQ4<>"", SUBSTITUTE(SUBSTITUTE(AQ4, "x", "*"&$O4&"^", 1), "x", "*"&$O4, 1), "")) -> FALSE | AM4: =IF($O4="", "", IF(AR4<>"", SUBSTITUTE(SUBSTITUTE(AR4, "x", "*"&$O4&"^", 1), "x", "*"&$O4, 1), "")) -> FALSE | AN4: =IF($O4="", "", IF(AS4<>"", SUBSTITUTE(SUBSTITUTE(AS4, "x", "*"&$O4&"^", 1), "x", "*"&$O4, 1), "")) -> FALSE | AO4: =IF($O4="", "FALSE", IF(AT4<>"FALSE", SUBSTITUTE(SUBSTITUTE(AT4, "x", "*"&$O4&"^", 1), "x", "*"&$O4, 1), "")) -> FALSE | AP4: =IF($O4="", "FALSE", IF(AU4<>"FALSE", SUBSTITUTE(SUBSTITUTE(AU4, "x", "*"&$O4&"^", 1), "x", "*"&$O4, 1), "")) -> FALSE | AQ4: =IF(AND(I4="TP",S4<=150),VLOOKUP(AF4,TPCalibEq150!$AZ$2:$BB$166,3,),IF(AND(I4="TDP",S4<=150),VLOOKUP(AF4,TPCalibEq150!$AZ$2:$BB$166,3,))) -> FALSE | AR4: =IF(AND(I4="TP",S4<=300),VLOOKUP(AF4,TPCalibEq300!$AZ$2:$BB$166,3,),IF(AND(I4="TDP",S4<=300),VLOOKUP(AF4,TPCalibEq300!$AZ$2:$BB$166,3,))) -> FALSE | AS4: =IF(AND(I4="TP",S4<=500),VLOOKUP(AF4,TPCalibEq500!$AZ$2:$BB$165,3,),IF(AND(I4="TDP",S4<=500),VLOOKUP(AF4,TPCalibEq500!$AZ$2:$BB$165,3,))) -> FALSE | AT4: =IF(AND(I4="TN",S4<=2800),VLOOKUP(AF4,TNCalibEq2500!$AZ$2:$BB$165,3,),IF(AND(I4="TDN",S4<=2800),VLOOKUP(AF4,TNCalibEq2500!$AZ$2:$BB$165,3,))) -> FALSE | AU4: =IF(I4="TP",VLOOKUP(AF4,TPCalibEqFull!$AZ$2:$BB$165,3),IF(I4="TDP",VLOOKUP(AF4,TPCalibEqFull!$AZ$2:$BB$165,3),IF(I4="TDN",VLOOKUP(AF4,TNCalibEqFull!$AZ$2:$BB$164,3),IF(I4="TN",VLOOKUP(AF4,TNCalibEqFull!$AZ$2:$BB$164,3),FALSE)))) -> FALSE | AV4: =TEXT(A4, "YYYYMMDD")&" "&TEXT(B4, "HH:MM:SS")&"-"&C4&"-"&D4&"-"&E4&"-"&F4&"-"&G4&"-"&H4 -> 20240727 00:00:00-1000-1-Sh-1-SW-UKN
A5: 45507 | B5: 0 | C5: 1000 | D5: 1 | E5: Dp | F5: 1 | G5: SW | H5: UKN | I5: TNH4 | J5: 3 | K5: 45687 | L5: 0.47097222 | M5: 1 | N5: N-1.1 | O5: 0.0453 | P5: 0.00622 | Q5: 2.75 | R5: ug-N/L | S5: =IF(OR(AND(I5<>"TP", I5<>"TDP",I5<>"TN", I5<>"TDN"),H5="CAL"), Q5*M5, IF(OR(AND(I5="TN", Q5>2500), AND(I5="TDN", Q5>2500)),MAX(Q5, AK5)*M5, IF(OR(AND(I5="TN", Q5<=2500), AND(I5="TDN", Q5<=2500)),MAX(Q5, AJ5,AK5)*M5, IF(OR(AND(I5="TP",Q5>500), AND(I5="TDP", Q5>500)),MAX(Q5,AK5)*M5,IF(OR(AND(I5="TP",Q5<=150), AND(I5="TDP", Q5<=150)),MAX(Q5,AG5:AI5,AK5)*M5,IF(OR(AND(I5="TP",Q5<=300), AND(I5="TDP", Q5<=300)),MAX(Q5,AH5,AI5,AK5)*M5,IF(OR(AND(I5="TP",Q5<=500), AND(I5="TDP", Q5<=500)),MAX(Q5,AI5,AK5)*M5,""))))))) -> 2.75 | T5: Conc = 0.169 * Area^2 + 60.8 * Area + 0.00 | U5: =IF(OR(H5="CHK",H5="ATP",H5="GUP",H5="PER", H5="NIC", H5="UREA"),(S5/V5*100),IF(H5="DUP",((ABS(S5-S4))/((S4+S5)/2))*100,IF(H5="SPK",((S5-S4)/V5*100),IF(OR(H5="LAB",H5="FLD",H5="ESF"),S5,"")))) | V5: =IF(H5="CHK",VLOOKUP(I5,QCCHK,3,),IF(H5="GUP",VLOOKUP(E5,QCGUP,2,),IF(AND(H5="ATP",OR(I5="TN",I5="TDN",I5="TNO2-3",I5="NO2-3")),VLOOKUP(E5,QCREC_N,2,),IF(AND(H5="NIC",OR(I5="TN",I5="TDN",I5="TNO2-3",I5="NO2-3")),VLOOKUP(E5,QCNIC_N,2,),IF(AND(H5="UREA",OR(I5="TN",I5="TDN",I5="TNO2-3",I5="NO2-3")),VLOOKUP(E5,QCUREA_N,2,),IF(H5="PER",VLOOKUP(I5,QCPER,MATCH(E5,QCACTUAL!$J$25:$AA$25,0),),IF(H5="SPK",VLOOKUP(I5,QCSPK,3,),IF(AND(H5="ATP",OR(I5="TP",I5="TDP")),VLOOKUP(E5,QCATP_P,2,),"")))))))) | W5: =IF(AND(OR(H5="PER",H5="ATP",H5="GUP",H5="CHK",H5="SPK", H5="NIC"),OR(U5>125,U5<75)),"FALSE",IF(AND(H5="DUP",OR(U5>25, U5<-25)),"FALSE",IF(AND(OR(H5="LAB",H5="FLD",H5="ESF"),U5>15),"FALSE","TRUE"))) -> TRUE | X5: =IF(ISNA(VLOOKUP(H5,QCEQUATIONS,2,)),"",(VLOOKUP(H5,QCEQUATIONS,2,))) | Y5: OM_1-30-2025_10-50-49AMadj-adj (8500).OMN | AL5: =IF($O5="", "", IF(AQ5<>"", SUBSTITUTE(SUBSTITUTE(AQ5, "x", "*"&$O5&"^", 1), "x", "*"&$O5, 1), "")) -> FALSE | AM5: =IF($O5="", "", IF(AR5<>"", SUBSTITUTE(SUBSTITUTE(AR5, "x", "*"&$O5&"^", 1), "x", "*"&$O5, 1), "")) -> FALSE | AN5: =IF($O5="", "", IF(AS5<>"", SUBSTITUTE(SUBSTITUTE(AS5, "x", "*"&$O5&"^", 1), "x", "*"&$O5, 1), "")) -> FALSE | AO5: =IF($O5="", "FALSE", IF(AT5<>"FALSE", SUBSTITUTE(SUBSTITUTE(AT5, "x", "*"&$O5&"^", 1), "x", "*"&$O5, 1), "")) -> FALSE | AP5: =IF($O5="", "FALSE", IF(AU5<>"FALSE", SUBSTITUTE(SUBSTITUTE(AU5, "x", "*"&$O5&"^", 1), "x", "*"&$O5, 1), "")) -> FALSE | AQ5: =IF(AND(I5="TP",S5<=150),VLOOKUP(AF5,TPCalibEq150!$AZ$2:$BB$166,3,),IF(AND(I5="TDP",S5<=150),VLOOKUP(AF5,TPCalibEq150!$AZ$2:$BB$166,3,))) -> FALSE | AR5: =IF(AND(I5="TP",S5<=300),VLOOKUP(AF5,TPCalibEq300!$AZ$2:$BB$166,3,),IF(AND(I5="TDP",S5<=300),VLOOKUP(AF5,TPCalibEq300!$AZ$2:$BB$166,3,))) -> FALSE | AS5: =IF(AND(I5="TP",S5<=500),VLOOKUP(AF5,TPCalibEq500!$AZ$2:$BB$165,3,),IF(AND(I5="TDP",S5<=500),VLOOKUP(AF5,TPCalibEq500!$AZ$2:$BB$165,3,))) -> FALSE | AT5: =IF(AND(I5="TN",S5<=2800),VLOOKUP(AF5,TNCalibEq2500!$AZ$2:$BB$165,3,),IF(AND(I5="TDN",S5<=2800),VLOOKUP(AF5,TNCalibEq2500!$AZ$2:$BB$165,3,))) -> FALSE | AU5: =IF(I5="TP",VLOOKUP(AF5,TPCalibEqFull!$AZ$2:$BB$165,3),IF(I5="TDP",VLOOKUP(AF5,TPCalibEqFull!$AZ$2:$BB$165,3),IF(I5="TDN",VLOOKUP(AF5,TNCalibEqFull!$AZ$2:$BB$164,3),IF(I5="TN",VLOOKUP(AF5,TNCalibEqFull!$AZ$2:$BB$164,3),FALSE)))) -> FALSE | AV5: =TEXT(A5, "YYYYMMDD")&" "&TEXT(B5, "HH:MM:SS")&"-"&C5&"-"&D5&"-"&E5&"-"&F5&"-"&G5&"-"&H5 -> 20240803 00:00:00-1000-1-Dp-1-SW-UKN
A6: 45507 | B6: 0 | C6: 1000 | D6: 2 | E6: Sh | F6: 1 | G6: DI | H6: BLK | I6: TNH4 | J6: 4 | K6: 45687 | L6: 0.47179398 | M6: 1 | N6: N-1.1 | O6: 1.64 | P6: 0.177 | Q6: 100 | R6: ug-N/L | S6: =IF(OR(AND(I6<>"TP", I6<>"TDP",I6<>"TN", I6<>"TDN"),H6="CAL"), Q6*M6, IF(OR(AND(I6="TN", Q6>2500), AND(I6="TDN", Q6>2500)),MAX(Q6, AK6)*M6, IF(OR(AND(I6="TN", Q6<=2500), AND(I6="TDN", Q6<=2500)),MAX(Q6, AJ6,AK6)*M6, IF(OR(AND(I6="TP",Q6>500), AND(I6="TDP", Q6>500)),MAX(Q6,AK6)*M6,IF(OR(AND(I6="TP",Q6<=150), AND(I6="TDP", Q6<=150)),MAX(Q6,AG6:AI6,AK6)*M6,IF(OR(AND(I6="TP",Q6<=300), AND(I6="TDP", Q6<=300)),MAX(Q6,AH6,AI6,AK6)*M6,IF(OR(AND(I6="TP",Q6<=500), AND(I6="TDP", Q6<=500)),MAX(Q6,AI6,AK6)*M6,""))))))) -> 100 | T6: Conc = 0.169 * Area^2 + 60.8 * Area + 0.00 | U6: =IF(OR(H6="CHK",H6="ATP",H6="GUP",H6="PER", H6="NIC", H6="UREA"),(S6/V6*100),IF(H6="DUP",((ABS(S6-S5))/((S5+S6)/2))*100,IF(H6="SPK",((S6-S5)/V6*100),IF(OR(H6="LAB",H6="FLD",H6="ESF"),S6,"")))) | V6: =IF(H6="CHK",VLOOKUP(I6,QCCHK,3,),IF(H6="GUP",VLOOKUP(E6,QCGUP,2,),IF(AND(H6="ATP",OR(I6="TN",I6="TDN",I6="TNO2-3",I6="NO2-3")),VLOOKUP(E6,QCREC_N,2,),IF(AND(H6="NIC",OR(I6="TN",I6="TDN",I6="TNO2-3",I6="NO2-3")),VLOOKUP(E6,QCNIC_N,2,),IF(AND(H6="UREA",OR(I6="TN",I6="TDN",I6="TNO2-3",I6="NO2-3")),VLOOKUP(E6,QCUREA_N,2,),IF(H6="PER",VLOOKUP(I6,QCPER,MATCH(E6,QCACTUAL!$J$25:$AA$25,0),),IF(H6="SPK",VLOOKUP(I6,QCSPK,3,),IF(AND(H6="ATP",OR(I6="TP",I6="TDP")),VLOOKUP(E6,QCATP_P,2,),"")))))))) | W6: =IF(AND(OR(H6="PER",H6="ATP",H6="GUP",H6="CHK",H6="SPK", H6="NIC"),OR(U6>125,U6<75)),"FALSE",IF(AND(H6="DUP",OR(U6>25, U6<-25)),"FALSE",IF(AND(OR(H6="LAB",H6="FLD",H6="ESF"),U6>15),"FALSE","TRUE"))) -> TRUE | X6: =IF(ISNA(VLOOKUP(H6,QCEQUATIONS,2,)),"",(VLOOKUP(H6,QCEQUATIONS,2,))) | Y6: OM_1-30-2025_10-50-49AMadj-adj (8500).OMN | AL6: =IF($O6="", "", IF(AQ6<>"", SUBSTITUTE(SUBSTITUTE(AQ6, "x", "*"&$O6&"^", 1), "x", "*"&$O6, 1), "")) -> FALSE | AM6: =IF($O6="", "", IF(AR6<>"", SUBSTITUTE(SUBSTITUTE(AR6, "x", "*"&$O6&"^", 1), "x", "*"&$O6, 1), "")) -> FALSE | AN6: =IF($O6="", "", IF(AS6<>"", SUBSTITUTE(SUBSTITUTE(AS6, "x", "*"&$O6&"^", 1), "x", "*"&$O6, 1), "")) -> FALSE | AO6: =IF($O6="", "FALSE", IF(AT6<>"FALSE", SUBSTITUTE(SUBSTITUTE(AT6, "x", "*"&$O6&"^", 1), "x", "*"&$O6, 1), "")) -> FALSE | AP6: =IF($O6="", "FALSE", IF(AU6<>"FALSE", SUBSTITUTE(SUBSTITUTE(AU6, "x", "*"&$O6&"^", 1), "x", "*"&$O6, 1), "")) -> FALSE | AQ6: =IF(AND(I6="TP",S6<=150),VLOOKUP(AF6,TPCalibEq150!$AZ$2:$BB$166,3,),IF(AND(I6="TDP",S6<=150),VLOOKUP(AF6,TPCalibEq150!$AZ$2:$BB$166,3,))) -> FALSE | AR6: =IF(AND(I6="TP",S6<=300),VLOOKUP(AF6,TPCalibEq300!$AZ$2:$BB$166,3,),IF(AND(I6="TDP",S6<=300),VLOOKUP(AF6,TPCalibEq300!$AZ$2:$BB$166,3,))) -> FALSE | AS6: =IF(AND(I6="TP",S6<=500),VLOOKUP(AF6,TPCalibEq500!$AZ$2:$BB$165,3,),IF(AND(I6="TDP",S6<=500),VLOOKUP(AF6,TPCalibEq500!$AZ$2:$BB$165,3,))) -> FALSE | AT6: =IF(AND(I6="TN",S6<=2800),VLOOKUP(AF6,TNCalibEq2500!$AZ$2:$BB$165,3,),IF(AND(I6="TDN",S6<=2800),VLOOKUP(AF6,TNCalibEq2500!$AZ$2:$BB$165,3,))) -> FALSE | AU6: =IF(I6="TP",VLOOKUP(AF6,TPCalibEqFull!$AZ$2:$BB$165,3),IF(I6="TDP",VLOOKUP(AF6,TPCalibEqFull!$AZ$2:$BB$165,3),IF(I6="TDN",VLOOKUP(AF6,TNCalibEqFull!$AZ$2:$BB$164,3),IF(I6="TN",VLOOKUP(AF6,TNCalibEqFull!$AZ$2:$BB$164,3),FALSE)))) -> FALSE | AV6: =TEXT(A6, "YYYYMMDD")&" "&TEXT(B6, "HH:MM:SS")&"-"&C6&"-"&D6&"-"&E6&"-"&F6&"-"&G6&"-"&H6 -> 20240803 00:00:00-1000-2-Sh-1-DI-BLK
A7: 45507 | B7: 0 | C7: 1000 | D7: 2 | E7: Sh | F7: 1 | G7: SW | H7: UKN | I7: TNH4 | J7: 5 | K7: 45687 | L7: 0.47259259 | M7: 1 | N7: N-1.1 | O7: 0.329 | P7: 0.0305 | Q7: 20 | R7: ug-N/L | S7: =IF(OR(AND(I7<>"TP", I7<>"TDP",I7<>"TN", I7<>"TDN"),H7="CAL"), Q7*M7, IF(OR(AND(I7="TN", Q7>2500), AND(I7="TDN", Q7>2500)),MAX(Q7, AK7)*M7, IF(OR(AND(I7="TN", Q7<=2500), AND(I7="TDN", Q7<=2500)),MAX(Q7, AJ7,AK7)*M7, IF(OR(AND(I7="TP",Q7>500), AND(I7="TDP", Q7>500)),MAX(Q7,AK7)*M7,IF(OR(AND(I7="TP",Q7<=150), AND(I7="TDP", Q7<=150)),MAX(Q7,AG7:AI7,AK7)*M7,IF(OR(AND(I7="TP",Q7<=300), AND(I7="TDP", Q7<=300)),MAX(Q7,AH7,AI7,AK7)*M7,IF(OR(AND(I7="TP",Q7<=500), AND(I7="TDP", Q7<=500)),MAX(Q7,AI7,AK7)*M7,""))))))) -> 20 | T7: Conc = 0.169 * Area^2 + 60.8 * Area + 0.00 | U7: =IF(OR(H7="CHK",H7="ATP",H7="GUP",H7="PER", H7="NIC", H7="UREA"),(S7/V7*100),IF(H7="DUP",((ABS(S7-S6))/((S6+S7)/2))*100,IF(H7="SPK",((S7-S6)/V7*100),IF(OR(H7="LAB",H7="FLD",H7="ESF"),S7,"")))) | V7: =IF(H7="CHK",VLOOKUP(I7,QCCHK,3,),IF(H7="GUP",VLOOKUP(E7,QCGUP,2,),IF(AND(H7="ATP",OR(I7="TN",I7="TDN",I7="TNO2-3",I7="NO2-3")),VLOOKUP(E7,QCREC_N,2,),IF(AND(H7="NIC",OR(I7="TN",I7="TDN",I7="TNO2-3",I7="NO2-3")),VLOOKUP(E7,QCNIC_N,2,),IF(AND(H7="UREA",OR(I7="TN",I7="TDN",I7="TNO2-3",I7="NO2-3")),VLOOKUP(E7,QCUREA_N,2,),IF(H7="PER",VLOOKUP(I7,QCPER,MATCH(E7,QCACTUAL!$J$25:$AA$25,0),),IF(H7="SPK",VLOOKUP(I7,QCSPK,3,),IF(AND(H7="ATP",OR(I7="TP",I7="TDP")),VLOOKUP(E7,QCATP_P,2,),"")))))))) | W7: =IF(AND(OR(H7="PER",H7="ATP",H7="GUP",H7="CHK",H7="SPK", H7="NIC"),OR(U7>125,U7<75)),"FALSE",IF(AND(H7="DUP",OR(U7>25, U7<-25)),"FALSE",IF(AND(OR(H7="LAB",H7="FLD",H7="ESF"),U7>15),"FALSE","TRUE"))) -> TRUE | X7: =IF(ISNA(VLOOKUP(H7,QCEQUATIONS,2,)),"",(VLOOKUP(H7,QCEQUATIONS,2,))) | Y7: OM_1-30-2025_10-50-49AMadj-adj (8500).OMN | AL7: =IF($O7="", "", IF(AQ7<>"", SUBSTITUTE(SUBSTITUTE(AQ7, "x", "*"&$O7&"^", 1), "x", "*"&$O7, 1), "")) -> FALSE | AM7: =IF($O7="", "", IF(AR7<>"", SUBSTITUTE(SUBSTITUTE(AR7, "x", "*"&$O7&"^", 1), "x", "*"&$O7, 1), "")) -> FALSE | AN7: =IF($O7="", "", IF(AS7<>"", SUBSTITUTE(SUBSTITUTE(AS7, "x", "*"&$O7&"^", 1), "x", "*"&$O7, 1), "")) -> FALSE | AO7: =IF($O7="", "FALSE", IF(AT7<>"FALSE", SUBSTITUTE(SUBSTITUTE(AT7, "x", "*"&$O7&"^", 1), "x", "*"&$O7, 1), "")) -> FALSE | AP7: =IF($O7="", "FALSE", IF(AU7<>"FALSE", SUBSTITUTE(SUBSTITUTE(AU7, "x", "*"&$O7&"^", 1), "x", "*"&$O7, 1), "")) -> FALSE | AQ7: =IF(AND(I7="TP",S7<=150),VLOOKUP(AF7,TPCalibEq150!$AZ$2:$BB$166,3,),IF(AND(I7="TDP",S7<=150),VLOOKUP(AF7,TPCalibEq150!$AZ$2:$BB$166,3,))) -> FALSE | AR7: =IF(AND(I7="TP",S7<=300),VLOOKUP(AF7,TPCalibEq300!$AZ$2:$BB$166,3,),IF(AND(I7="TDP",S7<=300),VLOOKUP(AF7,TPCalibEq300!$AZ$2:$BB$166,3,))) -> FALSE | AS7: =IF(AND(I7="TP",S7<=500),VLOOKUP(AF7,TPCalibEq500!$AZ$2:$BB$165,3,),IF(AND(I7="TDP",S7<=500),VLOOKUP(AF7,TPCalibEq500!$AZ$2:$BB$165,3,))) -> FALSE | AT7: =IF(AND(I7="TN",S7<=2800),VLOOKUP(AF7,TNCalibEq2500!$AZ$2:$BB$165,3,),IF(AND(I7="TDN",S7<=2800),VLOOKUP(AF7,TNCalibEq2500!$AZ$2:$BB$165,3,))) -> FALSE | AU7: =IF(I7="TP",VLOOKUP(AF7,TPCalibEqFull!$AZ$2:$BB$165,3),IF(I7="TDP",VLOOKUP(AF7,TPCalibEqFull!$AZ$2:$BB$165,3),IF(I7="TDN",VLOOKUP(AF7,TNCalibEqFull!$AZ$2:$BB$164,3),IF(I7="TN",VLOOKUP(AF7,TNCalibEqFull!$AZ$2:$BB$164,3),FALSE)))) -> FALSE | AV7: =TEXT(A7, "YYYYMMDD")&" "&TEXT(B7, "HH:MM:SS")&"-"&C7&"-"&D7&"-"&E7&"-"&F7&"-"&G7&"-"&H7 -> 20240803 00:00:00-1000-2-Sh-1-SW-UKN
A8: 45507 | B8: 0 | C8: 1000 | D8: 2 | E8: Sh | F8: 2 | G8: SW | H8: UKN | I8: TNH4 | J8: 6 | K8: 45687 | L8: 0.47340278 | M8: 1 | N8: N-1.1 | O8: 0.101 | P8: 0.00635 | Q8: 6.16 | R8: ug-N/L | S8: =IF(OR(AND(I8<>"TP", I8<>"TDP",I8<>"TN", I8<>"TDN"),H8="CAL"), Q8*M8, IF(OR(AND(I8="TN", Q8>2500), AND(I8="TDN", Q8>2500)),MAX(Q8, AK8)*M8, IF(OR(AND(I8="TN", Q8<=2500), AND(I8="TDN", Q8<=2500)),MAX(Q8, AJ8,AK8)*M8, IF(OR(AND(I8="TP",Q8>500), AND(I8="TDP", Q8>500)),MAX(Q8,AK8)*M8,IF(OR(AND(I8="TP",Q8<=150), AND(I8="TDP", Q8<=150)),MAX(Q8,AG8:AI8,AK8)*M8,IF(OR(AND(I8="TP",Q8<=300), AND(I8="TDP", Q8<=300)),MAX(Q8,AH8,AI8,AK8)*M8,IF(OR(AND(I8="TP",Q8<=500), AND(I8="TDP", Q8<=500)),MAX(Q8,AI8,AK8)*M8,""))))))) -> 6.16 | T8: Conc = 0.169 * Area^2 + 60.8 * Area + 0.00 | U8: =IF(OR(H8="CHK",H8="ATP",H8="GUP",H8="PER", H8="NIC", H8="UREA"),(S8/V8*100),IF(H8="DUP",((ABS(S8-S7))/((S7+S8)/2))*100,IF(H8="SPK",((S8-S7)/V8*100),IF(OR(H8="LAB",H8="FLD",H8="ESF"),S8,"")))) | V8: =IF(H8="CHK",VLOOKUP(I8,QCCHK,3,),IF(H8="GUP",VLOOKUP(E8,QCGUP,2,),IF(AND(H8="ATP",OR(I8="TN",I8="TDN",I8="TNO2-3",I8="NO2-3")),VLOOKUP(E8,QCREC_N,2,),IF(AND(H8="NIC",OR(I8="TN",I8="TDN",I8="TNO2-3",I8="NO2-3")),VLOOKUP(E8,QCNIC_N,2,),IF(AND(H8="UREA",OR(I8="TN",I8="TDN",I8="TNO2-3",I8="NO2-3")),VLOOKUP(E8,QCUREA_N,2,),IF(H8="PER",VLOOKUP(I8,QCPER,MATCH(E8,QCACTUAL!$J$25:$AA$25,0),),IF(H8="SPK",VLOOKUP(I8,QCSPK,3,),IF(AND(H8="ATP",OR(I8="TP",I8="TDP")),VLOOKUP(E8,QCATP_P,2,),"")))))))) | W8: =IF(AND(OR(H8="PER",H8="ATP",H8="GUP",H8="CHK",H8="SPK", H8="NIC"),OR(U8>125,U8<75)),"FALSE",IF(AND(H8="DUP",OR(U8>25, U8<-25)),"FALSE",IF(AND(OR(H8="LAB",H8="FLD",H8="ESF"),U8>15),"FALSE","TRUE"))) -> TRUE | X8: =IF(ISNA(VLOOKUP(H8,QCEQUATIONS,2,)),"",(VLOOKUP(H8,QCEQUATIONS,2,))) | Y8: OM_1-30-2025_10-50-49AMadj-adj (8500).OMN | AL8: =IF($O8="", "", IF(AQ8<>"", SUBSTITUTE(SUBSTITUTE(AQ8, "x", "*"&$O8&"^", 1), "x", "*"&$O8, 1), "")) -> FALSE | AM8: =IF($O8="", "", IF(AR8<>"", SUBSTITUTE(SUBSTITUTE(AR8, "x", "*"&$O8&"^", 1), "x", "*"&$O8, 1), "")) -> FALSE | AN8: =IF($O8="", "", IF(AS8<>"", SUBSTITUTE(SUBSTITUTE(AS8, "x", "*"&$O8&"^", 1), "x", "*"&$O8, 1), "")) -> FALSE | AO8: =IF($O8="", "FALSE", IF(AT8<>"FALSE", SUBSTITUTE(SUBSTITUTE(AT8, "x", "*"&$O8&"^", 1), "x", "*"&$O8, 1), "")) -> FALSE | AP8: =IF($O8="", "FALSE", IF(AU8<>"FALSE", SUBSTITUTE(SUBSTITUTE(AU8, "x", "*"&$O8&"^", 1), "x", "*"&$O8, 1), "")) -> FALSE | AQ8: =IF(AND(I8="TP",S8<=150),VLOOKUP(AF8,TPCalibEq150!$AZ$2:$BB$166,3,),IF(AND(I8="TDP",S8<=150),VLOOKUP(AF8,TPCalibEq150!$AZ$2:$BB$166,3,))) -> FALSE | AR8: =IF(AND(I8="TP",S8<=300),VLOOKUP(AF8,TPCalibEq300!$AZ$2:$BB$166,3,),IF(AND(I8="TDP",S8<=300),VLOOKUP(AF8,TPCalibEq300!$AZ$2:$BB$166,3,))) -> FALSE | AS8: =IF(AND(I8="TP",S8<=500),VLOOKUP(AF8,TPCalibEq500!$AZ$2:$BB$165,3,),IF(AND(I8="TDP",S8<=500),VLOOKUP(AF8,TPCalibEq500!$AZ$2:$BB$165,3,))) -> FALSE | AT8: =IF(AND(I8="TN",S8<=2800),VLOOKUP(AF8,TNCalibEq2500!$AZ$2:$BB$165,3,),IF(AND(I8="TDN",S8<=2800),VLOOKUP(AF8,TNCalibEq2500!$AZ$2:$BB$165,3,))) -> FALSE | AU8: =IF(I8="TP",VLOOKUP(AF8,TPCalibEqFull!$AZ$2:$BB$165,3),IF(I8="TDP",VLOOKUP(AF8,TPCalibEqFull!$AZ$2:$BB$165,3),IF(I8="TDN",VLOOKUP(AF8,TNCalibEqFull!$AZ$2:$BB$164,3),IF(I8="TN",VLOOKUP(AF8,TNCalibEqFull!$AZ$2:$BB$164,3),FALSE)))) -> FALSE | AV8: =TEXT(A8, "YYYYMMDD")&" "&TEXT(B8, "HH:MM:SS")&"-"&C8&"-"&D8&"-"&E8&"-"&F8&"-"&G8&"-"&H8 -> 20240803 00:00:00-1000-2-Sh-2-SW-UKN
A9: 45500 | B9: 0 | C9: 1000 | D9: 2 | E9: Dp | F9: 1 | G9: SW | H9: UKN | I9: TNH4 | J9: 7 | K9: 45687 | L9: 0.47422454 | M9: 1 | N9: N-1.1 | O9: 0.0132 | P9: 0.00161 | Q9: 0.801 | R9: ug-N/L | S9: =IF(OR(AND(I9<>"TP", I9<>"TDP",I9<>"TN", I9<>"TDN"),H9="CAL"), Q9*M9, IF(OR(AND(I9="TN", Q9>2500), AND(I9="TDN", Q9>2500)),MAX(Q9, AK9)*M9, IF(OR(AND(I9="TN", Q9<=2500), AND(I9="TDN", Q9<=2500)),MAX(Q9, AJ9,AK9)*M9, IF(OR(AND(I9="TP",Q9>500), AND(I9="TDP", Q9>500)),MAX(Q9,AK9)*M9,IF(OR(AND(I9="TP",Q9<=150), AND(I9="TDP", Q9<=150)),MAX(Q9,AG9:AI9,AK9)*M9,IF(OR(AND(I9="TP",Q9<=300), AND(I9="TDP", Q9<=300)),MAX(Q9,AH9,AI9,AK9)*M9,IF(OR(AND(I9="TP",Q9<=500), AND(I9="TDP", Q9<=500)),MAX(Q9,AI9,AK9)*M9,""))))))) -> 0.801 | T9: Conc = 0.169 * Area^2 + 60.8 * Area + 0.00 | U9: =IF(OR(H9="CHK",H9="ATP",H9="GUP",H9="PER", H9="NIC", H9="UREA"),(S9/V9*100),IF(H9="DUP",((ABS(S9-S8))/((S8+S9)/2))*100,IF(H9="SPK",((S9-S8)/V9*100),IF(OR(H9="LAB",H9="FLD",H9="ESF"),S9,"")))) | V9: =IF(H9="CHK",VLOOKUP(I9,QCCHK,3,),IF(H9="GUP",VLOOKUP(E9,QCGUP,2,),IF(AND(H9="ATP",OR(I9="TN",I9="TDN",I9="TNO2-3",I9="NO2-3")),VLOOKUP(E9,QCREC_N,2,),IF(AND(H9="NIC",OR(I9="TN",I9="TDN",I9="TNO2-3",I9="NO2-3")),VLOOKUP(E9,QCNIC_N,2,),IF(AND(H9="UREA",OR(I9="TN",I9="TDN",I9="TNO2-3",I9="NO2-3")),VLOOKUP(E9,QCUREA_N,2,),IF(H9="PER",VLOOKUP(I9,QCPER,MATCH(E9,QCACTUAL!$J$25:$AA$25,0),),IF(H9="SPK",VLOOKUP(I9,QCSPK,3,),IF(AND(H9="ATP",OR(I9="TP",I9="TDP")),VLOOKUP(E9,QCATP_P,2,),"")))))))) | W9: =IF(AND(OR(H9="PER",H9="ATP",H9="GUP",H9="CHK",H9="SPK", H9="NIC"),OR(U9>125,U9<75)),"FALSE",IF(AND(H9="DUP",OR(U9>25, U9<-25)),"FALSE",IF(AND(OR(H9="LAB",H9="FLD",H9="ESF"),U9>15),"FALSE","TRUE"))) -> TRUE | X9: =IF(ISNA(VLOOKUP(H9,QCEQUATIONS,2,)),"",(VLOOKUP(H9,QCEQUATIONS,2,))) | Y9: OM_1-30-2025_10-50-49AMadj-adj (8500).OMN | AL9: =IF($O9="", "", IF(AQ9<>"", SUBSTITUTE(SUBSTITUTE(AQ9, "x", "*"&$O9&"^", 1), "x", "*"&$O9, 1), "")) -> FALSE | AM9: =IF($O9="", "", IF(AR9<>"", SUBSTITUTE(SUBSTITUTE(AR9, "x", "*"&$O9&"^", 1), "x", "*"&$O9, 1), "")) -> FALSE | AN9: =IF($O9="", "", IF(AS9<>"", SUBSTITUTE(SUBSTITUTE(AS9, "x", "*"&$O9&"^", 1), "x", "*"&$O9, 1), "")) -> FALSE | AO9: =IF($O9="", "FALSE", IF(AT9<>"FALSE", SUBSTITUTE(SUBSTITUTE(AT9, "x", "*"&$O9&"^", 1), "x", "*"&$O9, 1), "")) -> FALSE | AP9: =IF($O9="", "FALSE", IF(AU9<>"FALSE", SUBSTITUTE(SUBSTITUTE(AU9, "x", "*"&$O9&"^", 1), "x", "*"&$O9, 1), "")) -> FALSE | AQ9: =IF(AND(I9="TP",S9<=150),VLOOKUP(AF9,TPCalibEq150!$AZ$2:$BB$166,3,),IF(AND(I9="TDP",S9<=150),VLOOKUP(AF9,TPCalibEq150!$AZ$2:$BB$166,3,))) -> FALSE | AR9: =IF(AND(I9="TP",S9<=300),VLOOKUP(AF9,TPCalibEq300!$AZ$2:$BB$166,3,),IF(AND(I9="TDP",S9<=300),VLOOKUP(AF9,TPCalibEq300!$AZ$2:$BB$166,3,))) -> FALSE | AS9: =IF(AND(I9="TP",S9<=500),VLOOKUP(AF9,TPCalibEq500!$AZ$2:$BB$165,3,),IF(AND(I9="TDP",S9<=500),VLOOKUP(AF9,TPCalibEq500!$AZ$2:$BB$165,3,))) -> FALSE | AT9: =IF(AND(I9="TN",S9<=2800),VLOOKUP(AF9,TNCalibEq2500!$AZ$2:$BB$165,3,),IF(AND(I9="TDN",S9<=2800),VLOOKUP(AF9,TNCalibEq2500!$AZ$2:$BB$165,3,))) -> FALSE | AU9: =IF(I9="TP",VLOOKUP(AF9,TPCalibEqFull!$AZ$2:$BB$165,3),IF(I9="TDP",VLOOKUP(AF9,TPCalibEqFull!$AZ$2:$BB$165,3),IF(I9="TDN",VLOOKUP(AF9,TNCalibEqFull!$AZ$2:$BB$164,3),IF(I9="TN",VLOOKUP(AF9,TNCalibEqFull!$AZ$2:$BB$164,3),FALSE)))) -> FALSE | AV9: =TEXT(A9, "YYYYMMDD")&" "&TEXT(B9, "HH:MM:SS")&"-"&C9&"-"&D9&"-"&E9&"-"&F9&"-"&G9&"-"&H9 -> 20240727 00:00:00-1000-2-Dp-1-SW-UKN
A10: 45500 | B10: 0 | C10: 1000 | D10: 3 | E10: Sh | F10: 1 | G10: DI | H10: BLK | I10: TNH4 | J10: 8 | K10: 45687 | L10: 0.47505787 | M10: 1 | N10: N-1.1 | O10: 0.28 | P10: 0.304 | Q10: 17 | R10: ug-N/L | S10: =IF(OR(AND(I10<>"TP", I10<>"TDP",I10<>"TN", I10<>"TDN"),H10="CAL"), Q10*M10, IF(OR(AND(I10="TN", Q10>2500), AND(I10="TDN", Q10>2500)),MAX(Q10, AK10)*M10, IF(OR(AND(I10="TN", Q10<=2500), AND(I10="TDN", Q10<=2500)),MAX(Q10, AJ10,AK10)*M10, IF(OR(AND(I10="TP",Q10>500), AND(I10="TDP", Q10>500)),MAX(Q10,AK10)*M10,IF(OR(AND(I10="TP",Q10<=150), AND(I10="TDP", Q10<=150)),MAX(Q10,AG10:AI10,AK10)*M10,IF(OR(AND(I10="TP",Q10<=300), AND(I10="TDP", Q10<=300)),MAX(Q10,AH10,AI10,AK10)*M10,IF(OR(AND(I10="TP",Q10<=500), AND(I10="TDP", Q10<=500)),MAX(Q10,AI10,AK10)*M10,""))))))) -> 17 | T10: Conc = 0.169 * Area^2 + 60.8 * Area + 0.00 | U10: =IF(OR(H10="CHK",H10="ATP",H10="GUP",H10="PER", H10="NIC", H10="UREA"),(S10/V10*100),IF(H10="DUP",((ABS(S10-S9))/((S9+S10)/2))*100,IF(H10="SPK",((S10-S9)/V10*100),IF(OR(H10="LAB",H10="FLD",H10="ESF"),S10,"")))) | V10: =IF(H10="CHK",VLOOKUP(I10,QCCHK,3,),IF(H10="GUP",VLOOKUP(E10,QCGUP,2,),IF(AND(H10="ATP",OR(I10="TN",I10="TDN",I10="TNO2-3",I10="NO2-3")),VLOOKUP(E10,QCREC_N,2,),IF(AND(H10="NIC",OR(I10="TN",I10="TDN",I10="TNO2-3",I10="NO2-3")),VLOOKUP(E10,QCNIC_N,2,),IF(AND(H10="UREA",OR(I10="TN",I10="TDN",I10="TNO2-3",I10="NO2-3")),VLOOKUP(E10,QCUREA_N,2,),IF(H10="PER",VLOOKUP(I10,QCPER,MATCH(E10,QCACTUAL!$J$25:$AA$25,0),),IF(H10="SPK",VLOOKUP(I10,QCSPK,3,),IF(AND(H10="ATP",OR(I10="TP",I10="TDP")),VLOOKUP(E10,QCATP_P,2,),"")))))))) | W10: =IF(AND(OR(H10="PER",H10="ATP",H10="GUP",H10="CHK",H10="SPK", H10="NIC"),OR(U10>125,U10<75)),"FALSE",IF(AND(H10="DUP",OR(U10>25, U10<-25)),"FALSE",IF(AND(OR(H10="LAB",H10="FLD",H10="ESF"),U10>15),"FALSE","TRUE"))) -> TRUE | X10: =IF(ISNA(VLOOKUP(H10,QCEQUATIONS,2,)),"",(VLOOKUP(H10,QCEQUATIONS,2,))) | Y10: OM_1-30-2025_10-50-49AMadj-adj (8500).OMN | AL10: =IF($O10="", "", IF(AQ10<>"", SUBSTITUTE(SUBSTITUTE(AQ10, "x", "*"&$O10&"^", 1), "x", "*"&$O10, 1), "")) -> FALSE | AM10: =IF($O10="", "", IF(AR10<>"", SUBSTITUTE(SUBSTITUTE(AR10, "x", "*"&$O10&"^", 1), "x", "*"&$O10, 1), "")) -> FALSE | AN10: =IF($O10="", "", IF(AS10<>"", SUBSTITUTE(SUBSTITUTE(AS10, "x", "*"&$O10&"^", 1), "x", "*"&$O10, 1), "")) -> FALSE | AO10: =IF($O10="", "FALSE", IF(AT10<>"FALSE", SUBSTITUTE(SUBSTITUTE(AT10, "x", "*"&$O10&"^", 1), "x", "*"&$O10, 1), "")) -> FALSE | AP10: =IF($O10="", "FALSE", IF(AU10<>"FALSE", SUBSTITUTE(SUBSTITUTE(AU10, "x", "*"&$O10&"^", 1), "x", "*"&$O10, 1), "")) -> FALSE | AQ10: =IF(AND(I10="TP",S10<=150),VLOOKUP(AF10,TPCalibEq150!$AZ$2:$BB$166,3,),IF(AND(I10="TDP",S10<=150),VLOOKUP(AF10,TPCalibEq150!$AZ$2:$BB$166,3,))) -> FALSE | AR10: =IF(AND(I10="TP",S10<=300),VLOOKUP(AF10,TPCalibEq300!$AZ$2:$BB$166,3,),IF(AND(I10="TDP",S10<=300),VLOOKUP(AF10,TPCalibEq300!$AZ$2:$BB$166,3,))) -> FALSE | AS10: =IF(AND(I10="TP",S10<=500),VLOOKUP(AF10,TPCalibEq500!$AZ$2:$BB$165,3,),IF(AND(I10="TDP",S10<=500),VLOOKUP(AF10,TPCalibEq500!$AZ$2:$BB$165,3,))) -> FALSE | AT10: =IF(AND(I10="TN",S10<=2800),VLOOKUP(AF10,TNCalibEq2500!$AZ$2:$BB$165,3,),IF(AND(I10="TDN",S10<=2800),VLOOKUP(AF10,TNCalibEq2500!$AZ$2:$BB$165,3,))) -> FALSE | AU10: =IF(I10="TP",VLOOKUP(AF10,TPCalibEqFull!$AZ$2:$BB$165,3),IF(I10="TDP",VLOOKUP(AF10,TPCalibEqFull!$AZ$2:$BB$165,3),IF(I10="TDN",VLOOKUP(AF10,TNCalibEqFull!$AZ$2:$BB$164,3),IF(I10="TN",VLOOKUP(AF10,TNCalibEqFull!$AZ$2:$BB$164,3),FALSE)))) -> FALSE | AV10: =TEXT(A10, "YYYYMMDD")&" "&TEXT(B10, "HH:MM:SS")&"-"&C10&"-"&D10&"-"&E10&"-"&F10&"-"&G10&"-"&H10 -> 20240727 00:00:00-1000-3-Sh-1-DI-BLK
A11: 45500 | B11: 0 | C11: 1000 | D11: 3 | E11: Sh | F11: 1 | G11: SW | H11: UKN | I11: TNH4 | J11: 9 | K11: 45687 | L11: 0.47587963 | M11: 1 | N11: N-1.1 | O11: 0.0639 | P11: 0.00991 | Q11: 3.88 | R11: ug-N/L | S11: =IF(OR(AND(I11<>"TP", I11<>"TDP",I11<>"TN", I11<>"TDN"),H11="CAL"), Q11*M11, IF(OR(AND(I11="TN", Q11>2500), AND(I11="TDN", Q11>2500)),MAX(Q11, AK11)*M11, IF(OR(AND(I11="TN", Q11<=2500), AND(I11="TDN", Q11<=2500)),MAX(Q11, AJ11,AK11)*M11, IF(OR(AND(I11="TP",Q11>500), AND(I11="TDP", Q11>500)),MAX(Q11,AK11)*M11,IF(OR(AND(I11="TP",Q11<=150), AND(I11="TDP", Q11<=150)),MAX(Q11,AG11:AI11,AK11)*M11,IF(OR(AND(I11="TP",Q11<=300), AND(I11="TDP", Q11<=300)),MAX(Q11,AH11,AI11,AK11)*M11,IF(OR(AND(I11="TP",Q11<=500), AND(I11="TDP", Q11<=500)),MAX(Q11,AI11,AK11)*M11,""))))))) -> 3.88 | T11: Conc = 0.169 * Area^2 + 60.8 * Area + 0.00 | U11: =IF(OR(H11="CHK",H11="ATP",H11="GUP",H11="PER", H11="NIC", H11="UREA"),(S11/V11*100),IF(H11="DUP",((ABS(S11-S10))/((S10+S11)/2))*100,IF(H11="SPK",((S11-S10)/V11*100),IF(OR(H11="LAB",H11="FLD",H11="ESF"),S11,"")))) | V11: =IF(H11="CHK",VLOOKUP(I11,QCCHK,3,),IF(H11="GUP",VLOOKUP(E11,QCGUP,2,),IF(AND(H11="ATP",OR(I11="TN",I11="TDN",I11="TNO2-3",I11="NO2-3")),VLOOKUP(E11,QCREC_N,2,),IF(AND(H11="NIC",OR(I11="TN",I11="TDN",I11="TNO2-3",I11="NO2-3")),VLOOKUP(E11,QCNIC_N,2,),IF(AND(H11="UREA",OR(I11="TN",I11="TDN",I11="TNO2-3",I11="NO2-3")),VLOOKUP(E11,QCUREA_N,2,),IF(H11="PER",VLOOKUP(I11,QCPER,MATCH(E11,QCACTUAL!$J$25:$AA$25,0),),IF(H11="SPK",VLOOKUP(I11,QCSPK,3,),IF(AND(H11="ATP",OR(I11="TP",I11="TDP")),VLOOKUP(E11,QCATP_P,2,),"")))))))) | W11: =IF(AND(OR(H11="PER",H11="ATP",H11="GUP",H11="CHK",H11="SPK", H11="NIC"),OR(U11>125,U11<75)),"FALSE",IF(AND(H11="DUP",OR(U11>25, U11<-25)),"FALSE",IF(AND(OR(H11="LAB",H11="FLD",H11="ESF"),U11>15),"FALSE","TRUE"))) -> TRUE | X11: =IF(ISNA(VLOOKUP(H11,QCEQUATIONS,2,)),"",(VLOOKUP(H11,QCEQUATIONS,2,))) | Y11: OM_1-30-2025_10-50-49AMadj-adj (8500).OMN | AL11: =IF($O11="", "", IF(AQ11<>"", SUBSTITUTE(SUBSTITUTE(AQ11, "x", "*"&$O11&"^", 1), "x", "*"&$O11, 1), "")) -> FALSE | AM11: =IF($O11="", "", IF(AR11<>"", SUBSTITUTE(SUBSTITUTE(AR11, "x", "*"&$O11&"^", 1), "x", "*"&$O11, 1), "")) -> FALSE | AN11: =IF($O11="", "", IF(AS11<>"", SUBSTITUTE(SUBSTITUTE(AS11, "x", "*"&$O11&"^", 1), "x", "*"&$O11, 1), "")) -> FALSE | AO11: =IF($O11="", "FALSE", IF(AT11<>"FALSE", SUBSTITUTE(SUBSTITUTE(AT11, "x", "*"&$O11&"^", 1), "x", "*"&$O11, 1), "")) -> FALSE | AP11: =IF($O11="", "FALSE", IF(AU11<>"FALSE", SUBSTITUTE(SUBSTITUTE(AU11, "x", "*"&$O11&"^", 1), "x", "*"&$O11, 1), "")) -> FALSE | AQ11: =IF(AND(I11="TP",S11<=150),VLOOKUP(AF11,TPCalibEq150!$AZ$2:$BB$166,3,),IF(AND(I11="TDP",S11<=150),VLOOKUP(AF11,TPCalibEq150!$AZ$2:$BB$166,3,))) -> FALSE | AR11: =IF(AND(I11="TP",S11<=300),VLOOKUP(AF11,TPCalibEq300!$AZ$2:$BB$166,3,),IF(AND(I11="TDP",S11<=300),VLOOKUP(AF11,TPCalibEq300!$AZ$2:$BB$166,3,))) -> FALSE | AS11: =IF(AND(I11="TP",S11<=500),VLOOKUP(AF11,TPCalibEq500!$AZ$2:$BB$165,3,),IF(AND(I11="TDP",S11<=500),VLOOKUP(AF11,TPCalibEq500!$AZ$2:$BB$165,3,))) -> FALSE | AT11: =IF(AND(I11="TN",S11<=2800),VLOOKUP(AF11,TNCalibEq2500!$AZ$2:$BB$165,3,),IF(AND(I11="TDN",S11<=2800),VLOOKUP(AF11,TNCalibEq2500!$AZ$2:$BB$165,3,))) -> FALSE | AU11: =IF(I11="TP",VLOOKUP(AF11,TPCalibEqFull!$AZ$2:$BB$165,3),IF(I11="TDP",VLOOKUP(AF11,TPCalibEqFull!$AZ$2:$BB$165,3),IF(I11="TDN",VLOOKUP(AF11,TNCalibEqFull!$AZ$2:$BB$164,3),IF(I11="TN",VLOOKUP(AF11,TNCalibEqFull!$AZ$2:$BB$164,3),FALSE)))) -> FALSE | AV11: =TEXT(A11, "YYYYMMDD")&" "&TEXT(B11, "HH:MM:SS")&"-"&C11&"-"&D11&"-"&E11&"-"&F11&"-"&G11&"-"&H11 -> 20240727 00:00:00-1000-3-Sh-1-SW-UKN
A12: 45500 | B12: 0 | C12: 1000 | D12: 3 | E12: Sh | F12: 2 | G12: SW | H12: UKN | I12: TNH4 | J12: 10 | K12: 45687 | L12: 0.47667824 | M12: 1 | N12: N-1.1 | O12: 0.0399 | P12: 0.0461 | Q12: 2.42 | R12: ug-N/L | S12: =IF(OR(AND(I12<>"TP", I12<>"TDP",I12<>"TN", I12<>"TDN"),H12="CAL"), Q12*M12, IF(OR(AND(I12="TN", Q12>2500), AND(I12="TDN", Q12>2500)),MAX(Q12, AK12)*M12, IF(OR(AND(I12="TN", Q12<=2500), AND(I12="TDN", Q12<=2500)),MAX(Q12, AJ12,AK12)*M12, IF(OR(AND(I12="TP",Q12>500), AND(I12="TDP", Q12>500)),MAX(Q12,AK12)*M12,IF(OR(AND(I12="TP",Q12<=150), AND(I12="TDP", Q12<=150)),MAX(Q12,AG12:AI12,AK12)*M12,IF(OR(AND(I12="TP",Q12<=300), AND(I12="TDP", Q12<=300)),MAX(Q12,AH12,AI12,AK12)*M12,IF(OR(AND(I12="TP",Q12<=500), AND(I12="TDP", Q12<=500)),MAX(Q12,AI12,AK12)*M12,""))))))) -> 2.42 | T12: Conc = 0.169 * Area^2 + 60.8 * Area + 0.00 | U12: =IF(OR(H12="CHK",H12="ATP",H12="GUP",H12="PER", H12="NIC", H12="UREA"),(S12/V12*100),IF(H12="DUP",((ABS(S12-S11))/((S11+S12)/2))*100,IF(H12="SPK",((S12-S11)/V12*100),IF(OR(H12="LAB",H12="FLD",H12="ESF"),S12,"")))) | V12: =IF(H12="CHK",VLOOKUP(I12,QCCHK,3,),IF(H12="GUP",VLOOKUP(E12,QCGUP,2,),IF(AND(H12="ATP",OR(I12="TN",I12="TDN",I12="TNO2-3",I12="NO2-3")),VLOOKUP(E12,QCREC_N,2,),IF(AND(H12="NIC",OR(I12="TN",I12="TDN",I12="TNO2-3",I12="NO2-3")),VLOOKUP(E12,QCNIC_N,2,),IF(AND(H12="UREA",OR(I12="TN",I12="TDN",I12="TNO2-3",I12="NO2-3")),VLOOKUP(E12,QCUREA_N,2,),IF(H12="PER",VLOOKUP(I12,QCPER,MATCH(E12,QCACTUAL!$J$25:$AA$25,0),),IF(H12="SPK",VLOOKUP(I12,QCSPK,3,),IF(AND(H12="ATP",OR(I12="TP",I12="TDP")),VLOOKUP(E12,QCATP_P,2,),"")))))))) | W12: =IF(AND(OR(H12="PER",H12="ATP",H12="GUP",H12="CHK",H12="SPK", H12="NIC"),OR(U12>125,U12<75)),"FALSE",IF(AND(H12="DUP",OR(U12>25, U12<-25)),"FALSE",IF(AND(OR(H12="LAB",H12="FLD",H12="ESF"),U12>15),"FALSE","TRUE"))) -> TRUE | X12: =IF(ISNA(VLOOKUP(H12,QCEQUATIONS,2,)),"",(VLOOKUP(H12,QCEQUATIONS,2,))) | Y12: OM_1-30-2025_10-50-49AMadj-adj (8500).OMN | AL12: =IF($O12="", "", IF(AQ12<>"", SUBSTITUTE(SUBSTITUTE(AQ12, "x", "*"&$O12&"^", 1), "x", "*"&$O12, 1), "")) -> FALSE | AM12: =IF($O12="", "", IF(AR12<>"", SUBSTITUTE(SUBSTITUTE(AR12, "x", "*"&$O12&"^", 1), "x", "*"&$O12, 1), "")) -> FALSE | AN12: =IF($O12="", "", IF(AS12<>"", SUBSTITUTE(SUBSTITUTE(AS12, "x", "*"&$O12&"^", 1), "x", "*"&$O12, 1), "")) -> FALSE | AO12: =IF($O12="", "FALSE", IF(AT12<>"FALSE", SUBSTITUTE(SUBSTITUTE(AT12, "x", "*"&$O12&"^", 1), "x", "*"&$O12, 1), "")) -> FALSE | AP12: =IF($O12="", "FALSE", IF(AU12<>"FALSE", SUBSTITUTE(SUBSTITUTE(AU12, "x", "*"&$O12&"^", 1), "x", "*"&$O12, 1), "")) -> FALSE | AQ12: =IF(AND(I12="TP",S12<=150),VLOOKUP(AF12,TPCalibEq150!$AZ$2:$BB$166,3,),IF(AND(I12="TDP",S12<=150),VLOOKUP(AF12,TPCalibEq150!$AZ$2:$BB$166,3,))) -> FALSE | AR12: =IF(AND(I12="TP",S12<=300),VLOOKUP(AF12,TPCalibEq300!$AZ$2:$BB$166,3,),IF(AND(I12="TDP",S12<=300),VLOOKUP(AF12,TPCalibEq300!$AZ$2:$BB$166,3,))) -> FALSE | AS12: =IF(AND(I12="TP",S12<=500),VLOOKUP(AF12,TPCalibEq500!$AZ$2:$BB$165,3,),IF(AND(I12="TDP",S12<=500),VLOOKUP(AF12,TPCalibEq500!$AZ$2:$BB$165,3,))) -> FALSE | AT12: =IF(AND(I12="TN",S12<=2800),VLOOKUP(AF12,TNCalibEq2500!$AZ$2:$BB$165,3,),IF(AND(I12="TDN",S12<=2800),VLOOKUP(AF12,TNCalibEq2500!$AZ$2:$BB$165,3,))) -> FALSE | AU12: =IF(I12="TP",VLOOKUP(AF12,TPCalibEqFull!$AZ$2:$BB$165,3),IF(I12="TDP",VLOOKUP(AF12,TPCalibEqFull!$AZ$2:$BB$165,3),IF(I12="TDN",VLOOKUP(AF12,TNCalibEqFull!$AZ$2:$BB$164,3),IF(I12="TN",VLOOKUP(AF12,TNCalibEqFull!$AZ$2:$BB$164,3),FALSE)))) -> FALSE | AV12: =TEXT(A12, "YYYYMMDD")&" "&TEXT(B12, "HH:MM:SS")&"-"&C12&"-"&D12&"-"&E12&"-"&F12&"-"&G12&"-"&H12 -> 20240727 00:00:00-1000-3-Sh-2-SW-UKN
A13: 45500 | B13: 0 | C13: 1000 | D13: 3 | E13: Dp | F13: 1 | G13: SW | H13: UKN | I13: TNH4 | J13: 11 | K13: 45687 | L13: 0.49199074 | M13: 10 | N13: N-1.1 | O13: 4.22 | P13: 0.498 | Q13: 260 | R13: ug-N/L | S13: =IF(OR(AND(I13<>"TP", I13<>"TDP",I13<>"TN", I13<>"TDN"),H13="CAL"), Q13*M13, IF(OR(AND(I13="TN", Q13>2500), AND(I13="TDN", Q13>2500)),MAX(Q13, AK13)*M13, IF(OR(AND(I13="TN", Q13<=2500), AND(I13="TDN", Q13<=2500)),MAX(Q13, AJ13,AK13)*M13, IF(OR(AND(I13="TP",Q13>500), AND(I13="TDP", Q13>500)),MAX(Q13,AK13)*M13,IF(OR(AND(I13="TP",Q13<=150), AND(I13="TDP", Q13<=150)),MAX(Q13,AG13:AI13,AK13)*M13,IF(OR(AND(I13="TP",Q13<=300), AND(I13="TDP", Q13<=300)),MAX(Q13,AH13,AI13,AK13)*M13,IF(OR(AND(I13="TP",Q13<=500), AND(I13="TDP", Q13<=500)),MAX(Q13,AI13,AK13)*M13,""))))))) -> 2600 | T13: Conc = 0.169 * Area^2 + 60.8 * Area + 0.00 | U13: =IF(OR(H13="CHK",H13="ATP",H13="GUP",H13="PER", H13="NIC", H13="UREA"),(S13/V13*100),IF(H13="DUP",((ABS(S13-S12))/((S12+S13)/2))*100,IF(H13="SPK",((S13-S12)/V13*100),IF(OR(H13="LAB",H13="FLD",H13="ESF"),S13,"")))) | V13: =IF(H13="CHK",VLOOKUP(I13,QCCHK,3,),IF(H13="GUP",VLOOKUP(E13,QCGUP,2,),IF(AND(H13="ATP",OR(I13="TN",I13="TDN",I13="TNO2-3",I13="NO2-3")),VLOOKUP(E13,QCREC_N,2,),IF(AND(H13="NIC",OR(I13="TN",I13="TDN",I13="TNO2-3",I13="NO2-3")),VLOOKUP(E13,QCNIC_N,2,),IF(AND(H13="UREA",OR(I13="TN",I13="TDN",I13="TNO2-3",I13="NO2-3")),VLOOKUP(E13,QCUREA_N,2,),IF(H13="PER",VLOOKUP(I13,QCPER,MATCH(E13,QCACTUAL!$J$25:$AA$25,0),),IF(H13="SPK",VLOOKUP(I13,QCSPK,3,),IF(AND(H13="ATP",OR(I13="TP",I13="TDP")),VLOOKUP(E13,QCATP_P,2,),"")))))))) | W13: =IF(AND(OR(H13="PER",H13="ATP",H13="GUP",H13="CHK",H13="SPK", H13="NIC"),OR(U13>125,U13<75)),"FALSE",IF(AND(H13="DUP",OR(U13>25, U13<-25)),"FALSE",IF(AND(OR(H13="LAB",H13="FLD",H13="ESF"),U13>15),"FALSE","TRUE"))) -> TRUE | X13: =IF(ISNA(VLOOKUP(H13,QCEQUATIONS,2,)),"",(VLOOKUP(H13,QCEQUATIONS,2,))) | Y13: OM_1-30-2025_10-50-49AMadj-adj (8500).OMN | AL13: =IF($O13="", "", IF(AQ13<>"", SUBSTITUTE(SUBSTITUTE(AQ13, "x", "*"&$O13&"^", 1), "x", "*"&$O13, 1), "")) -> FALSE | AM13: =IF($O13="", "", IF(AR13<>"", SUBSTITUTE(SUBSTITUTE(AR13, "x", "*"&$O13&"^", 1), "x", "*"&$O13, 1), "")) -> FALSE | AN13: =IF($O13="", "", IF(AS13<>"", SUBSTITUTE(SUBSTITUTE(AS13, "x", "*"&$O13&"^", 1), "x", "*"&$O13, 1), "")) -> FALSE | AO13: =IF($O13="", "FALSE", IF(AT13<>"FALSE", SUBSTITUTE(SUBSTITUTE(AT13, "x", "*"&$O13&"^", 1), "x", "*"&$O13, 1), "")) -> FALSE | AP13: =IF($O13="", "FALSE", IF(AU13<>"FALSE", SUBSTITUTE(SUBSTITUTE(AU13, "x", "*"&$O13&"^", 1), "x", "*"&$O13, 1), "")) -> FALSE | AQ13: =IF(AND(I13="TP",S13<=150),VLOOKUP(AF13,TPCalibEq150!$AZ$2:$BB$166,3,),IF(AND(I13="TDP",S13<=150),VLOOKUP(AF13,TPCalibEq150!$AZ$2:$BB$166,3,))) -> FALSE | AR13: =IF(AND(I13="TP",S13<=300),VLOOKUP(AF13,TPCalibEq300!$AZ$2:$BB$166,3,),IF(AND(I13="TDP",S13<=300),VLOOKUP(AF13,TPCalibEq300!$AZ$2:$BB$166,3,))) -> FALSE | AS13: =IF(AND(I13="TP",S13<=500),VLOOKUP(AF13,TPCalibEq500!$AZ$2:$BB$165,3,),IF(AND(I13="TDP",S13<=500),VLOOKUP(AF13,TPCalibEq500!$AZ$2:$BB$165,3,))) -> FALSE | AT13: =IF(AND(I13="TN",S13<=2800),VLOOKUP(AF13,TNCalibEq2500!$AZ$2:$BB$165,3,),IF(AND(I13="TDN",S13<=2800),VLOOKUP(AF13,TNCalibEq2500!$AZ$2:$BB$165,3,))) -> FALSE | AU13: =IF(I13="TP",VLOOKUP(AF13,TPCalibEqFull!$AZ$2:$BB$165,3),IF(I13="TDP",VLOOKUP(AF13,TPCalibEqFull!$AZ$2:$BB$165,3),IF(I13="TDN",VLOOKUP(AF13,TNCalibEqFull!$AZ$2:$BB$164,3),IF(I13="TN",VLOOKUP(AF13,TNCalibEqFull!$AZ$2:$BB$164,3),FALSE)))) -> FALSE | AV13: =TEXT(A13, "YYYYMMDD")&" "&TEXT(B13, "HH:MM:SS")&"-"&C13&"-"&D13&"-"&E13&"-"&F13&"-"&G13&"-"&H13 -> 20240727 00:00:00-1000-3-Dp-1-SW-UKN
A14: 45500 | B14: 0 | C14: 1000 | D14: 4 | E14: Sh | F14: 1 | G14: DI | H14: BLK | I14: TNH4 | J14: 12 | K14: 45687 | L14: 0.48076389 | M14: 1 | N14: N-1.1 | O14: 0.119 | P14: 0.0117 | Q14: 7.25 | R14: ug-N/L | S14: =IF(OR(AND(I14<>"TP", I14<>"TDP",I14<>"TN", I14<>"TDN"),H14="CAL"), Q14*M14, IF(OR(AND(I14="TN", Q14>2500), AND(I14="TDN", Q14>2500)),MAX(Q14, AK14)*M14, IF(OR(AND(I14="TN", Q14<=2500), AND(I14="TDN", Q14<=2500)),MAX(Q14, AJ14,AK14)*M14, IF(OR(AND(I14="TP",Q14>500), AND(I14="TDP", Q14>500)),MAX(Q14,AK14)*M14,IF(OR(AND(I14="TP",Q14<=150), AND(I14="TDP", Q14<=150)),MAX(Q14,AG14:AI14,AK14)*M14,IF(OR(AND(I14="TP",Q14<=300), AND(I14="TDP", Q14<=300)),MAX(Q14,AH14,AI14,AK14)*M14,IF(OR(AND(I14="TP",Q14<=500), AND(I14="TDP", Q14<=500)),MAX(Q14,AI14,AK14)*M14,""))))))) -> 7.25 | T14: Conc = 0.169 * Area^2 + 60.8 * Area + 0.00 | U14: =IF(OR(H14="CHK",H14="ATP",H14="GUP",H14="PER", H14="NIC", H14="UREA"),(S14/V14*100),IF(H14="DUP",((ABS(S14-#REF!))/((#REF!+S14)/2))*100,IF(H14="SPK",((S14-#REF!)/V14*100),IF(OR(H14="LAB",H14="FLD",H14="ESF"),S14,"")))) | V14: =IF(H14="CHK",VLOOKUP(I14,QCCHK,3,),IF(H14="GUP",VLOOKUP(E14,QCGUP,2,),IF(AND(H14="ATP",OR(I14="TN",I14="TDN",I14="TNO2-3",I14="NO2-3")),VLOOKUP(E14,QCREC_N,2,),IF(AND(H14="NIC",OR(I14="TN",I14="TDN",I14="TNO2-3",I14="NO2-3")),VLOOKUP(E14,QCNIC_N,2,),IF(AND(H14="UREA",OR(I14="TN",I14="TDN",I14="TNO2-3",I14="NO2-3")),VLOOKUP(E14,QCUREA_N,2,),IF(H14="PER",VLOOKUP(I14,QCPER,MATCH(E14,QCACTUAL!$J$25:$AA$25,0),),IF(H14="SPK",VLOOKUP(I14,QCSPK,3,),IF(AND(H14="ATP",OR(I14="TP",I14="TDP")),VLOOKUP(E14,QCATP_P,2,),"")))))))) | W14: =IF(AND(OR(H14="PER",H14="ATP",H14="GUP",H14="CHK",H14="SPK", H14="NIC"),OR(U14>125,U14<75)),"FALSE",IF(AND(H14="DUP",OR(U14>25, U14<-25)),"FALSE",IF(AND(OR(H14="LAB",H14="FLD",H14="ESF"),U14>15),"FALSE","TRUE"))) -> TRUE | X14: =IF(ISNA(VLOOKUP(H14,QCEQUATIONS,2,)),"",(VLOOKUP(H14,QCEQUATIONS,2,))) | Y14: OM_1-30-2025_10-50-49AMadj-adj (8500).OMN | AL14: =IF($O14="", "", IF(AQ14<>"", SUBSTITUTE(SUBSTITUTE(AQ14, "x", "*"&$O14&"^", 1), "x", "*"&$O14, 1), "")) -> FALSE | AM14: =IF($O14="", "", IF(AR14<>"", SUBSTITUTE(SUBSTITUTE(AR14, "x", "*"&$O14&"^", 1), "x", "*"&$O14, 1), "")) -> FALSE | AN14: =IF($O14="", "", IF(AS14<>"", SUBSTITUTE(SUBSTITUTE(AS14, "x", "*"&$O14&"^", 1), "x", "*"&$O14, 1), "")) -> FALSE | AO14: =IF($O14="", "FALSE", IF(AT14<>"FALSE", SUBSTITUTE(SUBSTITUTE(AT14, "x", "*"&$O14&"^", 1), "x", "*"&$O14, 1), "")) -> FALSE | AP14: =IF($O14="", "FALSE", IF(AU14<>"FALSE", SUBSTITUTE(SUBSTITUTE(AU14, "x", "*"&$O14&"^", 1), "x", "*"&$O14, 1), "")) -> FALSE | AQ14: =IF(AND(I14="TP",S14<=150),VLOOKUP(AF14,TPCalibEq150!$AZ$2:$BB$166,3,),IF(AND(I14="TDP",S14<=150),VLOOKUP(AF14,TPCalibEq150!$AZ$2:$BB$166,3,))) -> FALSE | AR14: =IF(AND(I14="TP",S14<=300),VLOOKUP(AF14,TPCalibEq300!$AZ$2:$BB$166,3,),IF(AND(I14="TDP",S14<=300),VLOOKUP(AF14,TPCalibEq300!$AZ$2:$BB$166,3,))) -> FALSE | AS14: =IF(AND(I14="TP",S14<=500),VLOOKUP(AF14,TPCalibEq500!$AZ$2:$BB$165,3,),IF(AND(I14="TDP",S14<=500),VLOOKUP(AF14,TPCalibEq500!$AZ$2:$BB$165,3,))) -> FALSE | AT14: =IF(AND(I14="TN",S14<=2800),VLOOKUP(AF14,TNCalibEq2500!$AZ$2:$BB$165,3,),IF(AND(I14="TDN",S14<=2800),VLOOKUP(AF14,TNCalibEq2500!$AZ$2:$BB$165,3,))) -> FALSE | AU14: =IF(I14="TP",VLOOKUP(AF14,TPCalibEqFull!$AZ$2:$BB$165,3),IF(I14="TDP",VLOOKUP(AF14,TPCalibEqFull!$AZ$2:$BB$165,3),IF(I14="TDN",VLOOKUP(AF14,TNCalibEqFull!$AZ$2:$BB$164,3),IF(I14="TN",VLOOKUP(AF14,TNCalibEqFull!$AZ$2:$BB$164,3),FALSE)))) -> FALSE | AV14: =TEXT(A14, "YYYYMMDD")&" "&TEXT(B14, "HH:MM:SS")&"-"&C14&"-"&D14&"-"&E14&"-"&F14&"-"&G14&"-"&H14 -> 20240727 00:00:00-1000-4-Sh-1-DI-BLK
A15: 45500 | B15: 0 | C15: 1000 | D15: 4 | E15: Sh | F15: 1 | G15: SW | H15: UKN | I15: TNH4 | J15: 13 | K15: 45687 | L15: 0.48157407 | M15: 1 | N15: N-1.1 | O15: 0.136 | P15: 0.0414 | Q15: 8.27 | R15: ug-N/L | S15: =IF(OR(AND(I15<>"TP", I15<>"TDP",I15<>"TN", I15<>"TDN"),H15="CAL"), Q15*M15, IF(OR(AND(I15="TN", Q15>2500), AND(I15="TDN", Q15>2500)),MAX(Q15, AK15)*M15, IF(OR(AND(I15="TN", Q15<=2500), AND(I15="TDN", Q15<=2500)),MAX(Q15, AJ15,AK15)*M15, IF(OR(AND(I15="TP",Q15>500), AND(I15="TDP", Q15>500)),MAX(Q15,AK15)*M15,IF(OR(AND(I15="TP",Q15<=150), AND(I15="TDP", Q15<=150)),MAX(Q15,AG15:AI15,AK15)*M15,IF(OR(AND(I15="TP",Q15<=300), AND(I15="TDP", Q15<=300)),MAX(Q15,AH15,AI15,AK15)*M15,IF(OR(AND(I15="TP",Q15<=500), AND(I15="TDP", Q15<=500)),MAX(Q15,AI15,AK15)*M15,""))))))) -> 8.27 | T15: Conc = 0.169 * Area^2 + 60.8 * Area + 0.00 | U15: =IF(OR(H15="CHK",H15="ATP",H15="GUP",H15="PER", H15="NIC", H15="UREA"),(S15/V15*100),IF(H15="DUP",((ABS(S15-S14))/((S14+S15)/2))*100,IF(H15="SPK",((S15-S14)/V15*100),IF(OR(H15="LAB",H15="FLD",H15="ESF"),S15,"")))) | V15: =IF(H15="CHK",VLOOKUP(I15,QCCHK,3,),IF(H15="GUP",VLOOKUP(E15,QCGUP,2,),IF(AND(H15="ATP",OR(I15="TN",I15="TDN",I15="TNO2-3",I15="NO2-3")),VLOOKUP(E15,QCREC_N,2,),IF(AND(H15="NIC",OR(I15="TN",I15="TDN",I15="TNO2-3",I15="NO2-3")),VLOOKUP(E15,QCNIC_N,2,),IF(AND(H15="UREA",OR(I15="TN",I15="TDN",I15="TNO2-3",I15="NO2-3")),VLOOKUP(E15,QCUREA_N,2,),IF(H15="PER",VLOOKUP(I15,QCPER,MATCH(E15,QCACTUAL!$J$25:$AA$25,0),),IF(H15="SPK",VLOOKUP(I15,QCSPK,3,),IF(AND(H15="ATP",OR(I15="TP",I15="TDP")),VLOOKUP(E15,QCATP_P,2,),"")))))))) | W15: =IF(AND(OR(H15="PER",H15="ATP",H15="GUP",H15="CHK",H15="SPK", H15="NIC"),OR(U15>125,U15<75)),"FALSE",IF(AND(H15="DUP",OR(U15>25, U15<-25)),"FALSE",IF(AND(OR(H15="LAB",H15="FLD",H15="ESF"),U15>15),"FALSE","TRUE"))) -> TRUE | X15: =IF(ISNA(VLOOKUP(H15,QCEQUATIONS,2,)),"",(VLOOKUP(H15,QCEQUATIONS,2,))) | Y15: OM_1-30-2025_10-50-49AMadj-adj (8500).OMN | AL15: =IF($O15="", "", IF(AQ15<>"", SUBSTITUTE(SUBSTITUTE(AQ15, "x", "*"&$O15&"^", 1), "x", "*"&$O15, 1), "")) -> FALSE | AM15: =IF($O15="", "", IF(AR15<>"", SUBSTITUTE(SUBSTITUTE(AR15, "x", "*"&$O15&"^", 1), "x", "*"&$O15, 1), "")) -> FALSE | AN15: =IF($O15="", "", IF(AS15<>"", SUBSTITUTE(SUBSTITUTE(AS15, "x", "*"&$O15&"^", 1), "x", "*"&$O15, 1), "")) -> FALSE | AO15: =IF($O15="", "FALSE", IF(AT15<>"FALSE", SUBSTITUTE(SUBSTITUTE(AT15, "x", "*"&$O15&"^", 1), "x", "*"&$O15, 1), "")) -> FALSE | AP15: =IF($O15="", "FALSE", IF(AU15<>"FALSE", SUBSTITUTE(SUBSTITUTE(AU15, "x", "*"&$O15&"^", 1), "x", "*"&$O15, 1), "")) -> FALSE | AQ15: =IF(AND(I15="TP",S15<=150),VLOOKUP(AF15,TPCalibEq150!$AZ$2:$BB$166,3,),IF(AND(I15="TDP",S15<=150),VLOOKUP(AF15,TPCalibEq150!$AZ$2:$BB$166,3,))) -> FALSE | AR15: =IF(AND(I15="TP",S15<=300),VLOOKUP(AF15,TPCalibEq300!$AZ$2:$BB$166,3,),IF(AND(I15="TDP",S15<=300),VLOOKUP(AF15,TPCalibEq300!$AZ$2:$BB$166,3,))) -> FALSE | AS15: =IF(AND(I15="TP",S15<=500),VLOOKUP(AF15,TPCalibEq500!$AZ$2:$BB$165,3,),IF(AND(I15="TDP",S15<=500),VLOOKUP(AF15,TPCalibEq500!$AZ$2:$BB$165,3,))) -> FALSE | AT15: =IF(AND(I15="TN",S15<=2800),VLOOKUP(AF15,TNCalibEq2500!$AZ$2:$BB$165,3,),IF(AND(I15="TDN",S15<=2800),VLOOKUP(AF15,TNCalibEq2500!$AZ$2:$BB$165,3,))) -> FALSE | AU15: =IF(I15="TP",VLOOKUP(AF15,TPCalibEqFull!$AZ$2:$BB$165,3),IF(I15="TDP",VLOOKUP(AF15,TPCalibEqFull!$AZ$2:$BB$165,3),IF(I15="TDN",VLOOKUP(AF15,TNCalibEqFull!$AZ$2:$BB$164,3),IF(I15="TN",VLOOKUP(AF15,TNCalibEqFull!$AZ$2:$BB$164,3),FALSE)))) -> FALSE | AV15: =TEXT(A15, "YYYYMMDD")&" "&TEXT(B15, "HH:MM:SS")&"-"&C15&"-"&D15&"-"&E15&"-"&F15&"-"&G15&"-"&H15 -> 20240727 00:00:00-1000-4-Sh-1-SW-UKN
A16: 45500 | B16: 0 | C16: 1000 | D16: 4 | E16: Sh | F16: 2 | G16: SW | H16: UKN | I16: TNH4 | J16: 14 | K16: 45687 | L16: 0.48238426 | M16: 1 | N16: N-1.1 | O16: 0.0167 | P16: 0.0033 | Q16: 1.01 | R16: ug-N/L | S16: =IF(OR(AND(I16<>"TP", I16<>"TDP",I16<>"TN", I16<>"TDN"),H16="CAL"), Q16*M16, IF(OR(AND(I16="TN", Q16>2500), AND(I16="TDN", Q16>2500)),MAX(Q16, AK16)*M16, IF(OR(AND(I16="TN", Q16<=2500), AND(I16="TDN", Q16<=2500)),MAX(Q16, AJ16,AK16)*M16, IF(OR(AND(I16="TP",Q16>500), AND(I16="TDP", Q16>500)),MAX(Q16,AK16)*M16,IF(OR(AND(I16="TP",Q16<=150), AND(I16="TDP", Q16<=150)),MAX(Q16,AG16:AI16,AK16)*M16,IF(OR(AND(I16="TP",Q16<=300), AND(I16="TDP", Q16<=300)),MAX(Q16,AH16,AI16,AK16)*M16,IF(OR(AND(I16="TP",Q16<=500), AND(I16="TDP", Q16<=500)),MAX(Q16,AI16,AK16)*M16,""))))))) -> 1.01 | T16: Conc = 0.169 * Area^2 + 60.8 * Area + 0.00 | U16: =IF(OR(H16="CHK",H16="ATP",H16="GUP",H16="PER", H16="NIC", H16="UREA"),(S16/V16*100),IF(H16="DUP",((ABS(S16-S15))/((S15+S16)/2))*100,IF(H16="SPK",((S16-S15)/V16*100),IF(OR(H16="LAB",H16="FLD",H16="ESF"),S16,"")))) | V16: =IF(H16="CHK",VLOOKUP(I16,QCCHK,3,),IF(H16="GUP",VLOOKUP(E16,QCGUP,2,),IF(AND(H16="ATP",OR(I16="TN",I16="TDN",I16="TNO2-3",I16="NO2-3")),VLOOKUP(E16,QCREC_N,2,),IF(AND(H16="NIC",OR(I16="TN",I16="TDN",I16="TNO2-3",I16="NO2-3")),VLOOKUP(E16,QCNIC_N,2,),IF(AND(H16="UREA",OR(I16="TN",I16="TDN",I16="TNO2-3",I16="NO2-3")),VLOOKUP(E16,QCUREA_N,2,),IF(H16="PER",VLOOKUP(I16,QCPER,MATCH(E16,QCACTUAL!$J$25:$AA$25,0),),IF(H16="SPK",VLOOKUP(I16,QCSPK,3,),IF(AND(H16="ATP",OR(I16="TP",I16="TDP")),VLOOKUP(E16,QCATP_P,2,),"")))))))) | W16: =IF(AND(OR(H16="PER",H16="ATP",H16="GUP",H16="CHK",H16="SPK", H16="NIC"),OR(U16>125,U16<75)),"FALSE",IF(AND(H16="DUP",OR(U16>25, U16<-25)),"FALSE",IF(AND(OR(H16="LAB",H16="FLD",H16="ESF"),U16>15),"FALSE","TRUE"))) -> TRUE | X16: =IF(ISNA(VLOOKUP(H16,QCEQUATIONS,2,)),"",(VLOOKUP(H16,QCEQUATIONS,2,))) | Y16: OM_1-30-2025_10-50-49AMadj-adj (8500).OMN | AL16: =IF($O16="", "", IF(AQ16<>"", SUBSTITUTE(SUBSTITUTE(AQ16, "x", "*"&$O16&"^", 1), "x", "*"&$O16, 1), "")) -> FALSE | AM16: =IF($O16="", "", IF(AR16<>"", SUBSTITUTE(SUBSTITUTE(AR16, "x", "*"&$O16&"^", 1), "x", "*"&$O16, 1), "")) -> FALSE | AN16: =IF($O16="", "", IF(AS16<>"", SUBSTITUTE(SUBSTITUTE(AS16, "x", "*"&$O16&"^", 1), "x", "*"&$O16, 1), "")) -> FALSE | AO16: =IF($O16="", "FALSE", IF(AT16<>"FALSE", SUBSTITUTE(SUBSTITUTE(AT16, "x", "*"&$O16&"^", 1), "x", "*"&$O16, 1), "")) -> FALSE | AP16: =IF($O16="", "FALSE", IF(AU16<>"FALSE", SUBSTITUTE(SUBSTITUTE(AU16, "x", "*"&$O16&"^", 1), "x", "*"&$O16, 1), "")) -> FALSE | AQ16: =IF(AND(I16="TP",S16<=150),VLOOKUP(AF16,TPCalibEq150!$AZ$2:$BB$166,3,),IF(AND(I16="TDP",S16<=150),VLOOKUP(AF16,TPCalibEq150!$AZ$2:$BB$166,3,))) -> FALSE | AR16: =IF(AND(I16="TP",S16<=300),VLOOKUP(AF16,TPCalibEq300!$AZ$2:$BB$166,3,),IF(AND(I16="TDP",S16<=300),VLOOKUP(AF16,TPCalibEq300!$AZ$2:$BB$166,3,))) -> FALSE | AS16: =IF(AND(I16="TP",S16<=500),VLOOKUP(AF16,TPCalibEq500!$AZ$2:$BB$165,3,),IF(AND(I16="TDP",S16<=500),VLOOKUP(AF16,TPCalibEq500!$AZ$2:$BB$165,3,))) -> FALSE | AT16: =IF(AND(I16="TN",S16<=2800),VLOOKUP(AF16,TNCalibEq2500!$AZ$2:$BB$165,3,),IF(AND(I16="TDN",S16<=2800),VLOOKUP(AF16,TNCalibEq2500!$AZ$2:$BB$165,3,))) -> FALSE | AU16: =IF(I16="TP",VLOOKUP(AF16,TPCalibEqFull!$AZ$2:$BB$165,3),IF(I16="TDP",VLOOKUP(AF16,TPCalibEqFull!$AZ$2:$BB$165,3),IF(I16="TDN",VLOOKUP(AF16,TNCalibEqFull!$AZ$2:$BB$164,3),IF(I16="TN",VLOOKUP(AF16,TNCalibEqFull!$AZ$2:$BB$164,3),FALSE)))) -> FALSE | AV16: =TEXT(A16, "YYYYMMDD")&" "&TEXT(B16, "HH:MM:SS")&"-"&C16&"-"&D16&"-"&E16&"-"&F16&"-"&G16&"-"&H16 -> 20240727 00:00:00-1000-4-Sh-2-SW-UKN
A17: 45500 | B17: 0 | C17: 1000 | D17: 4 | E17: Dp | F17: 1 | G17: SW | H17: UKN | I17: TNH4 | J17: 15 | K17: 45687 | L17: 0.49115741 | M17: 1 | N17: N-1.1 | O17: 0.213 | P17: 0.113 | Q17: 12.9 | R17: ug-N/L | S17: =IF(OR(AND(I17<>"TP", I17<>"TDP",I17<>"TN", I17<>"TDN"),H17="CAL"), Q17*M17, IF(OR(AND(I17="TN", Q17>2500), AND(I17="TDN", Q17>2500)),MAX(Q17, AK17)*M17, IF(OR(AND(I17="TN", Q17<=2500), AND(I17="TDN", Q17<=2500)),MAX(Q17, AJ17,AK17)*M17, IF(OR(AND(I17="TP",Q17>500), AND(I17="TDP", Q17>500)),MAX(Q17,AK17)*M17,IF(OR(AND(I17="TP",Q17<=150), AND(I17="TDP", Q17<=150)),MAX(Q17,AG17:AI17,AK17)*M17,IF(OR(AND(I17="TP",Q17<=300), AND(I17="TDP", Q17<=300)),MAX(Q17,AH17,AI17,AK17)*M17,IF(OR(AND(I17="TP",Q17<=500), AND(I17="TDP", Q17<=500)),MAX(Q17,AI17,AK17)*M17,""))))))) -> 12.9 | T17: Conc = 0.169 * Area^2 + 60.8 * Area + 0.00 | U17: =IF(OR(H17="CHK",H17="ATP",H17="GUP",H17="PER", H17="NIC", H17="UREA"),(S17/V17*100),IF(H17="DUP",((ABS(S17-S16))/((S16+S17)/2))*100,IF(H17="SPK",((S17-S16)/V17*100),IF(OR(H17="LAB",H17="FLD",H17="ESF"),S17,"")))) | V17: =IF(H17="CHK",VLOOKUP(I17,QCCHK,3,),IF(H17="GUP",VLOOKUP(E17,QCGUP,2,),IF(AND(H17="ATP",OR(I17="TN",I17="TDN",I17="TNO2-3",I17="NO2-3")),VLOOKUP(E17,QCREC_N,2,),IF(AND(H17="NIC",OR(I17="TN",I17="TDN",I17="TNO2-3",I17="NO2-3")),VLOOKUP(E17,QCNIC_N,2,),IF(AND(H17="UREA",OR(I17="TN",I17="TDN",I17="TNO2-3",I17="NO2-3")),VLOOKUP(E17,QCUREA_N,2,),IF(H17="PER",VLOOKUP(I17,QCPER,MATCH(E17,QCACTUAL!$J$25:$AA$25,0),),IF(H17="SPK",VLOOKUP(I17,QCSPK,3,),IF(AND(H17="ATP",OR(I17="TP",I17="TDP")),VLOOKUP(E17,QCATP_P,2,),"")))))))) | W17: =IF(AND(OR(H17="PER",H17="ATP",H17="GUP",H17="CHK",H17="SPK", H17="NIC"),OR(U17>125,U17<75)),"FALSE",IF(AND(H17="DUP",OR(U17>25, U17<-25)),"FALSE",IF(AND(OR(H17="LAB",H17="FLD",H17="ESF"),U17>15),"FALSE","TRUE"))) -> TRUE | X17: =IF(ISNA(VLOOKUP(H17,QCEQUATIONS,2,)),"",(VLOOKUP(H17,QCEQUATIONS,2,))) | Y17: OM_1-30-2025_10-50-49AMadj-adj (8500).OMN | AL17: =IF($O17="", "", IF(AQ17<>"", SUBSTITUTE(SUBSTITUTE(AQ17, "x", "*"&$O17&"^", 1), "x", "*"&$O17, 1), "")) -> FALSE | AM17: =IF($O17="", "", IF(AR17<>"", SUBSTITUTE(SUBSTITUTE(AR17, "x", "*"&$O17&"^", 1), "x", "*"&$O17, 1), "")) -> FALSE | AN17: =IF($O17="", "", IF(AS17<>"", SUBSTITUTE(SUBSTITUTE(AS17, "x", "*"&$O17&"^", 1), "x", "*"&$O17, 1), "")) -> FALSE | AO17: =IF($O17="", "FALSE", IF(AT17<>"FALSE", SUBSTITUTE(SUBSTITUTE(AT17, "x", "*"&$O17&"^", 1), "x", "*"&$O17, 1), "")) -> FALSE | AP17: =IF($O17="", "FALSE", IF(AU17<>"FALSE", SUBSTITUTE(SUBSTITUTE(AU17, "x", "*"&$O17&"^", 1), "x", "*"&$O17, 1), "")) -> FALSE | AQ17: =IF(AND(I17="TP",S17<=150),VLOOKUP(AF17,TPCalibEq150!$AZ$2:$BB$166,3,),IF(AND(I17="TDP",S17<=150),VLOOKUP(AF17,TPCalibEq150!$AZ$2:$BB$166,3,))) -> FALSE | AR17: =IF(AND(I17="TP",S17<=300),VLOOKUP(AF17,TPCalibEq300!$AZ$2:$BB$166,3,),IF(AND(I17="TDP",S17<=300),VLOOKUP(AF17,TPCalibEq300!$AZ$2:$BB$166,3,))) -> FALSE | AS17: =IF(AND(I17="TP",S17<=500),VLOOKUP(AF17,TPCalibEq500!$AZ$2:$BB$165,3,),IF(AND(I17="TDP",S17<=500),VLOOKUP(AF17,TPCalibEq500!$AZ$2:$BB$165,3,))) -> FALSE | AT17: =IF(AND(I17="TN",S17<=2800),VLOOKUP(AF17,TNCalibEq2500!$AZ$2:$BB$165,3,),IF(AND(I17="TDN",S17<=2800),VLOOKUP(AF17,TNCalibEq2500!$AZ$2:$BB$165,3,))) -> FALSE | AU17: =IF(I17="TP",VLOOKUP(AF17,TPCalibEqFull!$AZ$2:$BB$165,3),IF(I17="TDP",VLOOKUP(AF17,TPCalibEqFull!$AZ$2:$BB$165,3),IF(I17="TDN",VLOOKUP(AF17,TNCalibEqFull!$AZ$2:$BB$164,3),IF(I17="TN",VLOOKUP(AF17,TNCalibEqFull!$AZ$2:$BB$164,3),FALSE)))) -> FALSE | AV17: =TEXT(A17, "YYYYMMDD")&" "&TEXT(B17, "HH:MM:SS")&"-"&C17&"-"&D17&"-"&E17&"-"&F17&"-"&G17&"-"&H17 -> 20240727 00:00:00-1000-4-Dp-1-SW-UKN
A18: 45507 | B18: 0 | C18: 1000 | D18: 9 | E18: Sh | F18: 1 | G18: DI | H18: BLK | I18: TNH4 | J18: 16 | K18: 45687 | L18: 0.49282407 | M18: 1 | N18: N-1.1 | O18: 0.12 | P18: 0.0189 | Q18: 7.28 | R18: ug-N/L | S18: =IF(OR(AND(I18<>"TP", I18<>"TDP",I18<>"TN", I18<>"TDN"),H18="CAL"), Q18*M18, IF(OR(AND(I18="TN", Q18>2500), AND(I18="TDN", Q18>2500)),MAX(Q18, AK18)*M18, IF(OR(AND(I18="TN", Q18<=2500), AND(I18="TDN", Q18<=2500)),MAX(Q18, AJ18,AK18)*M18, IF(OR(AND(I18="TP",Q18>500), AND(I18="TDP", Q18>500)),MAX(Q18,AK18)*M18,IF(OR(AND(I18="TP",Q18<=150), AND(I18="TDP", Q18<=150)),MAX(Q18,AG18:AI18,AK18)*M18,IF(OR(AND(I18="TP",Q18<=300), AND(I18="TDP", Q18<=300)),MAX(Q18,AH18,AI18,AK18)*M18,IF(OR(AND(I18="TP",Q18<=500), AND(I18="TDP", Q18<=500)),MAX(Q18,AI18,AK18)*M18,""))))))) -> 7.28 | T18: Conc = 0.169 * Area^2 + 60.8 * Area + 0.00 | U18: =IF(OR(H18="CHK",H18="ATP",H18="GUP",H18="PER", H18="NIC", H18="UREA"),(S18/V18*100),IF(H18="DUP",((ABS(S18-S17))/((S17+S18)/2))*100,IF(H18="SPK",((S18-S17)/V18*100),IF(OR(H18="LAB",H18="FLD",H18="ESF"),S18,"")))) | V18: =IF(H18="CHK",VLOOKUP(I18,QCCHK,3,),IF(H18="GUP",VLOOKUP(E18,QCGUP,2,),IF(AND(H18="ATP",OR(I18="TN",I18="TDN",I18="TNO2-3",I18="NO2-3")),VLOOKUP(E18,QCREC_N,2,),IF(AND(H18="NIC",OR(I18="TN",I18="TDN",I18="TNO2-3",I18="NO2-3")),VLOOKUP(E18,QCNIC_N,2,),IF(AND(H18="UREA",OR(I18="TN",I18="TDN",I18="TNO2-3",I18="NO2-3")),VLOOKUP(E18,QCUREA_N,2,),IF(H18="PER",VLOOKUP(I18,QCPER,MATCH(E18,QCACTUAL!$J$25:$AA$25,0),),IF(H18="SPK",VLOOKUP(I18,QCSPK,3,),IF(AND(H18="ATP",OR(I18="TP",I18="TDP")),VLOOKUP(E18,QCATP_P,2,),"")))))))) | W18: =IF(AND(OR(H18="PER",H18="ATP",H18="GUP",H18="CHK",H18="SPK", H18="NIC"),OR(U18>125,U18<75)),"FALSE",IF(AND(H18="DUP",OR(U18>25, U18<-25)),"FALSE",IF(AND(OR(H18="LAB",H18="FLD",H18="ESF"),U18>15),"FALSE","TRUE"))) -> TRUE | X18: =IF(ISNA(VLOOKUP(H18,QCEQUATIONS,2,)),"",(VLOOKUP(H18,QCEQUATIONS,2,))) | Y18: OM_1-30-2025_10-50-49AMadj-adj (8500).OMN | AL18: =IF($O18="", "", IF(AQ18<>"", SUBSTITUTE(SUBSTITUTE(AQ18, "x", "*"&$O18&"^", 1), "x", "*"&$O18, 1), "")) -> FALSE | AM18: =IF($O18="", "", IF(AR18<>"", SUBSTITUTE(SUBSTITUTE(AR18, "x", "*"&$O18&"^", 1), "x", "*"&$O18, 1), "")) -> FALSE | AN18: =IF($O18="", "", IF(AS18<>"", SUBSTITUTE(SUBSTITUTE(AS18, "x", "*"&$O18&"^", 1), "x", "*"&$O18, 1), "")) -> FALSE | AO18: =IF($O18="", "FALSE", IF(AT18<>"FALSE", SUBSTITUTE(SUBSTITUTE(AT18, "x", "*"&$O18&"^", 1), "x", "*"&$O18, 1), "")) -> FALSE | AP18: =IF($O18="", "FALSE", IF(AU18<>"FALSE", SUBSTITUTE(SUBSTITUTE(AU18, "x", "*"&$O18&"^", 1), "x", "*"&$O18, 1), "")) -> FALSE | AQ18: =IF(AND(I18="TP",S18<=150),VLOOKUP(AF18,TPCalibEq150!$AZ$2:$BB$166,3,),IF(AND(I18="TDP",S18<=150),VLOOKUP(AF18,TPCalibEq150!$AZ$2:$BB$166,3,))) -> FALSE | AR18: =IF(AND(I18="TP",S18<=300),VLOOKUP(AF18,TPCalibEq300!$AZ$2:$BB$166,3,),IF(AND(I18="TDP",S18<=300),VLOOKUP(AF18,TPCalibEq300!$AZ$2:$BB$166,3,))) -> FALSE | AS18: =IF(AND(I18="TP",S18<=500),VLOOKUP(AF18,TPCalibEq500!$AZ$2:$BB$165,3,),IF(AND(I18="TDP",S18<=500),VLOOKUP(AF18,TPCalibEq500!$AZ$2:$BB$165,3,))) -> FALSE | AT18: =IF(AND(I18="TN",S18<=2800),VLOOKUP(AF18,TNCalibEq2500!$AZ$2:$BB$165,3,),IF(AND(I18="TDN",S18<=2800),VLOOKUP(AF18,TNCalibEq2500!$AZ$2:$BB$165,3,))) -> FALSE | AU18: =IF(I18="TP",VLOOKUP(AF18,TPCalibEqFull!$AZ$2:$BB$165,3),IF(I18="TDP",VLOOKUP(AF18,TPCalibEqFull!$AZ$2:$BB$165,3),IF(I18="TDN",VLOOKUP(AF18,TNCalibEqFull!$AZ$2:$BB$164,3),IF(I18="TN",VLOOKUP(AF18,TNCalibEqFull!$AZ$2:$BB$164,3),FALSE)))) -> FALSE | AV18: =TEXT(A18, "YYYYMMDD")&" "&TEXT(B18, "HH:MM:SS")&"-"&C18&"-"&D18&"-"&E18&"-"&F18&"-"&G18&"-"&H18 -> 20240803 00:00:00-1000-9-Sh-1-DI-BLK
